Workbook

Sheet 审核目录
A1: 阶段质量审核记录目录
A2: 项目：相控阵数字样机软件 | C2: 阶段：需求分析阶段
A4: 流水号 | B4: 审核对象 | C4: 检查单 | D4: 审核报告
A5: 5 | B5: 相控阵数字样机软件开发计划 | C5: 打开检查单 | D5: 打开审核报告
A6: 6 | B6: 相控阵数字样机软件测量分析计划 | C6: 打开检查单 | D6: 打开审核报告
A7: 7 | B7: 相控阵数字样机软件质量保证计划 | C7: 打开检查单 | D7: 打开审核报告
A8: 8 | B8: 相控阵数字样机软件配置管理计划 | C8: 打开检查单 | D8: 打开审核报告
A9: 9 | B9: 审核项目策划过程 | C9: 打开检查单 | D9: 打开审核报告
A10: 10 | B10: 审核项目监控过程-双周 | C10: 打开检查单 | D10: 打开审核报告
A11: 11 | B11: 审核测量与绩效管理过程-双周 | C11: 打开检查单 | D11: 打开审核报告
A12: 12 | B12: 相控阵数字样机软件需求规格说明 | C12: 打开检查单 | D12: 打开审核报告
A13: 13 | B13: 相控阵数字样机软件测试计划 | C13: 打开检查单 | D13: 打开审核报告
A14: 14 | B14: 审核验证与确认过程 | C14: 打开检查单 | D14: 打开审核报告
A15: 15 | B15: 审核需求开发与管理过程 | C15: 打开检查单 | D15: 打开审核报告
A16: 16 | B16: 审核配置管理过程-阶段 | C16: 打开检查单 | D16: 打开审核报告
... A18: 18 | B18: 审核测量与绩效管理过程-阶段 | C18: 打开检查单 | D18: 打开审核报告

Sheet 阶段质量审核工作报告
A1: 质量审核工作报告
A2: 编号：ZDPX-03046/0.0-QA-质量报告-002
A3: 项目名称 | C3: 相控阵数字样机软件 | G3: 报告阶段 | I3: 需求分析阶段
A4: 报告起止日期 | C4: 2025-12-29 至 2026-01-23 | G4: 项目QA | I4: 高蕾
A6: 审核情况汇总
A7: 流水号 | B7: 审核对象 | C7: 审核日期 | D7: 节点 | E7: NC类型 | F7: 问题描述 | J7: 严重程度 | K7: 是否关闭 | L7: 审核状态
A8: 双周汇总：2026-01-12
A9: 5 | B9: 相控阵数字样机软件开发计划 | C9: 2026-01-06 | D9: 双周 | F9: 未发现不符合项 | L9: 未确认
A10: 6 | B10: ='_计算'!B2 | C10: 2026-01-06 | D10: 双周 | E10: ='_计算'!D2 | F10: ='_计算'!E2 | J10: ='_计算'!F2 | K10: ='_计算'!G2 | L10: 未确认
A11: 6 | B11: ='_计算'!B3 | C11: 2026-01-06 | D11: 双周 | E11: ='_计算'!D3 | F11: ='_计算'!E3 | J11: ='_计算'!F3 | K11: ='_计算'!G3 | L11: 未确认
A12: 7 | B12: ='_计算'!B4 | C12: 2026-01-06 | D12: 双周 | E12: ='_计算'!D4 | F12: ='_计算'!E4 | J12: ='_计算'!F4 | K12: ='_计算'!G4 | L12: 未确认
A13: 7 | B13: ='_计算'!B5 | C13: 2026-01-06 | D13: 双周 | E13: ='_计算'!D5 | F13: ='_计算'!E5 | J13: ='_计算'!F5 | K13: ='_计算'!G5 | L13: 未确认
A14: 8 | B14: 相控阵数字样机软件配置管理计划 | C14: 2026-01-06 | D14: 双周 | F14: 未发现不符合项 | L14: 未确认
A15: 9 | B15: 审核项目策划过程 | C15: 2026-01-08 | D15: 双周 | F15: 未发现不符合项 | L15: 未确认
A16: 10 | B16: ='_计算'!B6 | C16: 2026-01-12 | D16: 双周 | E16: ='_计算'!D6 | F16: ='_计算'!E6 | J16: ='_计算'!F6 | K16: ='_计算'!G6 | L16: 未确认
A17: 11 | B17: ='_计算'!B7 | C17: 2026-01-12 | D17: 双周 | E17: ='_计算'!D7 | F17: ='_计算'!E7 | J17: ='_计算'!F7 | K17: ='_计算'!G7 | L17: 未确认
A18: 11 | B18: ='_计算'!B8 | C18: 2026-01-12 | D18: 双周 | E18: ='_计算'!D8 | F18: ='_计算'!E8 | J18: ='_计算'!F8 | K18: ='_计算'!G8 | L18: 未确认
A19: 节点统计 | E19: NC总数 | F19: =COUNTIF(J9:J18,"?*") | G19: 未关闭 | H19: =COUNTIF(K9:K18,"否") | I19: 严重 | J19: =COUNTIF(J9:J18,"严重")
A21: 阶段汇总：2026-01-23
A22: 12 | B22: ='_计算'!B9 | C22: 2026-01-15 | D22: 阶段 | E22: ='_计算'!D9 | F22: ='_计算'!E9 | J22: ='_计算'!F9 | K22: ='_计算'!G9 | L22: 未确认
A23: 12 | B23: ='_计算'!B10 | C23: 2026-01-15 | D23: 阶段 | E23: ='_计算'!D10 | F23: ='_计算'!E10 | J23: ='_计算'!F10 | K23: ='_计算'!G10 | L23: 未确认
A24: 13 | B24: ='_计算'!B11 | C24: 2026-01-21 | D24: 阶段 | E24: ='_计算'!D11 | F24: ='_计算'!E11 | J24: ='_计算'!F11 | K24: ='_计算'!G11 | L24: 未确认
A25: 13 | B25: ='_计算'!B12 | C25: 2026-01-21 | D25: 阶段 | E25: ='_计算'!D12 | F25: ='_计算'!E12 | J25: ='_计算'!F12 | K25: ='_计算'!G12 | L25: 未确认
A26: 14 | B26: ='_计算'!B13 | C26: 2026-01-23 | D26: 阶段 | E26: ='_计算'!D13 | F26: ='_计算'!E13 | J26: ='_计算'!F13 | K26: ='_计算'!G13 | L26: 未确认
A27: 14 | B27: ='_计算'!B14 | C27: 2026-01-23 | D27: 阶段 | E27: ='_计算'!D14 | F27: ='_计算'!E14 | J27: ='_计算'!F14 | K27: ='_计算'!G14 | L27: 未确认
A28: 15 | B28: ='_计算'!B15 | C28: 2026-01-23 | D28: 阶段 | E28: ='_计算'!D15 | F28: ='_计算'!E15 | J28: ='_计算'!F15 | K28: ='_计算'!G15 | L28: 未确认
A29: 15 | B29: ='_计算'!B16 | C29: 2026-01-23 | D29: 阶段 | E29: ='_计算'!D16 | F29: ='_计算'!E16 | J29: ='_计算'!F16 | K29: ='_计算'!G16 | L29: 未确认
A30: 16 | B30: ='_计算'!B17 | C30: 2026-01-23 | D30: 阶段 | E30: ='_计算'!D17 | F30: ='_计算'!E17 | J30: ='_计算'!F17 | K30: ='_计算'!G17 | L30: 未确认
A31: 16 | B31: ='_计算'!B18 | C31: 2026-01-23 | D31: 阶段 | E31: ='_计算'!D18 | F31: ='_计算'!E18 | J31: ='_计算'!F18 | K31: ='_计算'!G18 | L31: 未确认
A32: 17 | B32: ='_计算'!B19 | C32: 2026-01-23 | D32: 阶段 | E32: ='_计算'!D19 | F32: ='_计算'!E19 | J32: ='_计算'!F19 | K32: ='_计算'!G19 | L32: 未确认
A33: 17 | B33: ='_计算'!B20 | C33: 2026-01-23 | D33: 阶段 | E33: ='_计算'!D20 | F33: ='_计算'!E20 | J33: ='_计算'!F20 | K33: ='_计算'!G20 | L33: 未确认
A34: 18 | B34: ='_计算'!B21 | C34: 2026-01-23 | D34: 阶段 | E34: ='_计算'!D21 | F34: ='_计算'!E21 | J34: ='_计算'!F21 | K34: ='_计算'!G21 | L34: 未确认
A35: 节点统计 | E35: NC总数 | F35: =COUNTIF(J22:J34,"?*") | G35: 未关闭 | H35: =COUNTIF(K22:K34,"否") | I35: 严重 | J35: =COUNTIF(J22:J34,"严重")
A37: 阶段汇总统计
A38: 产品NC总数 | B38: =COUNTIF('_计算'!D2:D21,"工作产品") | C38: 过程NC总数 | D38: =COUNTIFS('_计算'!D2:D21,"<>工作产品",'_计算'!D2:D21,"<>") | E38: 未关闭NC数 | F38: =COUNTIF('_计算'!G2:G21,"否") | G38: 轻微 | H38: =COUNTIF('_计算'!F2:F21,"轻微") | I38: 一般 | J38: =COUNTIF('_计算'!F2:F21,"一般") | K38: 严重 | L38: =COUNTIF('_计算'!F2:F21,"严重")
A39: RDM | B39: PP | C39: PMC | D39: CM | E39: MT | F39: MPM | G39: VV | H39: II | I39: 工作产品 | J39: 总计
A40: =COUNTIF('_计算'!D2:D21,"RDM") | B40: =COUNTIF('_计算'!D2:D21,"PP") | C40: =COUNTIF('_计算'!D2:D21,"PMC") | D40: =COUNTIF('_计算'!D2:D21,"CM") | E40: =COUNTIF('_计算'!D2:D21,"MT") | F40: =COUNTIF('_计算'!D2:D21,"MPM") | G40: =COUNTIF('_计算'!D2:D21,"VV") | H40: =COUNTIF('_计算'!D2:D21,"II") | I40: =COUNTIF('_计算'!D2:D21,"工作产品") | J40: =SUM(A40:I40)

Sheet C005-相控阵数字样机软件开发计划
A1: 软件开发计划检查单
A2: 编号：ZDPX-03046/0.0-QA-检查单-005
A3: 项目名称 | C3: 相控阵数字样机软件 | F3: 当前阶段 | H3: 需求分析阶段 | J3: 项目QA | L3: 高蕾
A4: 审核对象 | C4: 相控阵数字样机软件开发计划 | F4: 产品标识 | H4: ZDPX03046/0.0-KFJH | J4: 产品版本 | L4: V1.0
A6: 序号 | B6: 审核内容 | G6: 是 | H6: 否 | I6: 不适用 | J6: 严重程度 | L6: 备注
A7: 通用检查项
A8: 1 | B8: 是否符合有关模板的格式要求。 | G8: ✓
A9: 2 | B9: 是否完整、准确地描述本计划和其它相关项目管理计划的关系（软件配置管理计划、软件质量保证计划、测量与分析计划等）。 | G9: ✓
A10: 3* | B10: 是否描述了所选用的软件生存周期模型，且说明了选择理由？ | G10: ✓
A11: 4 | B11: 是否定义了软件开发过程，并说明了裁剪对象及原因？ | G11: ✓
A12: 5 | B12: 是否描述了要使用的软件开发方法且合理可行。 | G12: ✓
A13: 6 | B13: 是否完整、准确地描述了在软件需求分析、设计、编码、测试方面要遵循的标准且与软件研制任务书的要求一致 | G13: ✓
A14: 7* | B14: WBS是否完整、准确地描述了软件产品结构并与软件研制任务书的要求一致。 | G14: ✓
A15: 8 | B15: 是否准确地描述了可重用软件产品。 | G15: ✓
A16: 9 | B16: 是否准确地描述了关键性需求的处理方法。 | G16: ✓
A17: 10 | B17: 是否完整、准确地描述了验证与确认计划？ | G17: ✓
A18: 11* | B18: 是否完整、准确地描述了软件开发过程中里程碑点的名称、建立条件、完成时间等，且与软件研制任务书的要求一致。 | G18: ✓
A19: 12* | B19: 进度表是否完整、准确地描述了阶段名称、工作内容和要求、开始结束时间、启动准则、完成准则且与软件研制任务书的要求一致。 | G19: ✓
... A32: 25 | B32: 是否建立起软件开发计划与软件研制任务书的追踪关系？追踪关系是否正确？ | G32: ✓
A34: 不符合项问题明细
A35: 问题ID | B35: 检查项 | C35: 问题描述 | F35: 严重程度 | G35: 责任人 | H35: 提交日期 | I35: 计划关闭日期 | J35: 纠正措施 | L35: 关闭
A36: 本次审核未发现不符合项。

Sheet R005-相控阵数字样机软件开发计划
B1: 过程/产品审核报告
B2: 编号：ZDPX-03046/0.0-QA-审核报告-005
B3: 项目名称 | D3: 相控阵数字样机软件 | H3: 所处阶段 | J3: 需求分析阶段
B4: 审核对象（过程名称/产品名称） | F4: 相控阵数字样机软件开发计划
B5: 审核人 | D5: 高蕾 | F5: 审核日期 | H5: 2026-01-06
B6: 审核依据 | D6: ZDPX-03046/0.0-QA-检查单-005
B7: 本次审核依据《软件开发计划检查单》实施。经审核，未发现不符合项。
B9: NC总数 | D9: 轻微 | F9: 一般 | H9: 严重
B10: =0 | D10: =0 | F10: =0 | H10: =0
B11: 不符合项问题（NC）列表
B12: 序号 | C12: 问题描述 | F12: 严重程度 | G12: 责任人 | H12: 提交日期 | I12: 计划关闭日期 | J12: 纠正措施
B13: 本次审核未发现不符合项。
B15: 纠正措施验证情况：
B16: 不适用

Sheet C006-相控阵数字样机软件测量分析计划
A1: 软件测量与分析计划检查单
A2: 编号：ZDPX-03046/0.0-QA-检查单-006
A3: 项目名称 | C3: 相控阵数字样机软件 | F3: 当前阶段 | H3: 需求分析阶段 | J3: 项目QA | L3: 高蕾
A4: 审核对象 | C4: 相控阵数字样机软件测量分析计划 | F4: 产品标识 | H4: ZDPX03046/0.0-CLJH | J4: 产品版本 | L4: V1.0
A6: 序号 | B6: 审核内容 | G6: 是 | H6: 否 | I6: 不适用 | J6: 严重程度 | L6: 备注
A7: 通用检查项
A8: 1 | B8: 是否符合有关模板的格式要求？ | G8: ✓
A9: 2 | B9: 是否完整、准确地描述了项目测量活动的背景信息与项目特征？且与相关计划（软件开发计划、软件质量保证计划和软件配置管理计划）保持一致？ | G9: ✓
A10: 3 | B10: 是否明确了参加测量分析工作的相关人员及其职责？ | H10: ✓ | J10: 一般 | K10: 必要内容覆盖不完整
A11: 4 | B11: 项目管理目标是否明确且合理可行？ | G11: ✓
A12: 5* | B12: 与项目管理目标对应的测量目标和测量项是否描述清晰且无遗漏？ | H12: ✓ | J12: 严重 | K12: 必要内容覆盖不完整
A13: 6 | B13: 是否明确描述了使用测量项进行项目状态分析的频率？ | G13: ✓
A14: 7* | B14: 是否标识了测量时机？且与相关计划（软件开发计划、软件质量保证计划和软件配置管理计划）的活动和阶段检查点保持一致？ | G14: ✓
A15: 8 | B15: 是否标识了各测量任务的时间段、测量项、结果形式、测量负责人等必要信息？ | G15: ✓
A17: 不符合项问题明细
A18: 问题ID | B18: 检查项 | C18: 问题描述 | F18: 严重程度 | G18: 责任人 | H18: 提交日期 | I18: 计划关闭日期 | J18: 纠正措施 | L18: 关闭
A19: 5 | B19: 3 | C19: 相关工作产品未完整覆盖本检查项要求的必要内容和适用场景，当前结果不能支撑该项要求已经全部落实。 | F19: 一般 | G19: 赵要浦 | H19: 2026-01-06 | I19: 2026-01-07 | J19: 补齐遗漏内容和适用场景，核对相关输入后组织复核，并保留复核结论。 | L19: 否
A20: 6 | B20: 5 | C20: 相关工作产品未完整覆盖本检查项要求的必要内容和适用场景，当前结果不能支撑该项要求已经全部落实。 | F20: 严重 | G20: 赵要浦 | H20: 2026-01-06 | I20: 2026-01-07 | J20: 补齐遗漏内容和适用场景，核对相关输入后组织复核，并保留复核结论。 | L20: 否

Sheet R006-相控阵数字样机软件测量分析计划
B1: 过程/产品审核报告
B2: 编号：ZDPX-03046/0.0-QA-审核报告-006
B3: 项目名称 | D3: 相控阵数字样机软件 | H3: 所处阶段 | J3: 需求分析阶段
B4: 审核对象（过程名称/产品名称） | F4: 相控阵数字样机软件测量分析计划
B5: 审核人 | D5: 高蕾 | F5: 审核日期 | H5: 2026-01-06
B6: 审核依据 | D6: ZDPX-03046/0.0-QA-检查单-006
B7: 本次审核依据《软件测量与分析计划检查单》实施。经审核，发现2个不符合项。
B9: NC总数 | D9: 轻微 | F9: 一般 | H9: 严重
B10: =COUNTIF(B13:B14,"<>") | D10: =COUNTIF(F13:F14,"轻微") | F10: =COUNTIF(F13:F14,"一般") | H10: =COUNTIF(F13:F14,"严重")
B11: 不符合项问题（NC）列表
B12: 序号 | C12: 问题描述 | F12: 严重程度 | G12: 责任人 | H12: 提交日期 | I12: 计划关闭日期 | J12: 纠正措施
B13: 1 | C13: ='C006-相控阵数字样机软件测量分析计划'!C19 | F13: ='C006-相控阵数字样机软件测量分析计划'!F19 | G13: ='C006-相控阵数字样机软件测量分析计划'!G19 | H13: ='C006-相控阵数字样机软件测量分析计划'!H19 | I13: ='C006-相控阵数字样机软件测量分析计划'!I19 | J13: ='C006-相控阵数字样机软件测量分析计划'!J19
B14: 2 | C14: ='C006-相控阵数字样机软件测量分析计划'!C20 | F14: ='C006-相控阵数字样机软件测量分析计划'!F20 | G14: ='C006-相控阵数字样机软件测量分析计划'!G20 | H14: ='C006-相控阵数字样机软件测量分析计划'!H20 | I14: ='C006-相控阵数字样机软件测量分析计划'!I20 | J14: ='C006-相控阵数字样机软件测量分析计划'!J20
B16: 纠正措施验证情况：
B17: 已整改并验证通过；已整改并验证通过

Sheet C007-相控阵数字样机软件质量保证计划
A1: 软件质量保证计划检查单
A2: 编号：ZDPX-03046/0.0-QA-检查单-007
A3: 项目名称 | C3: 相控阵数字样机软件 | F3: 当前阶段 | H3: 需求分析阶段 | J3: 项目QA | L3: 高蕾
A4: 审核对象 | C4: 相控阵数字样机软件质量保证计划 | F4: 产品标识 | H4: ZDPX03046/0.0-ZBJH | J4: 产品版本 | L4: V1.0
A6: 序号 | B6: 审核内容 | G6: 是 | H6: 否 | I6: 不适用 | J6: 严重程度 | L6: 备注
A7: 通用检查项
A8: 1 | B8: 格式与排版是否与模板要求一致。 | G8: ✓
A9: 2 | B9: 是否完整、准确地描述了项目软件开发过程中所应遵循的各种技术性和管理性标准和规范。 | G9: ✓
A10: 3 | B10: 是否正确地描述了软件质量保证人员及相关配合人员的职责和权限。 | G10: ✓
A11: 4 | B11: 是否完整、准确地描述了实施软件质量保证任务所需的工具、设施且与软件开发计划一致。 | G11: ✓
A12: 5* | B12: 是否完整、准确地列出了本项目软件开发生存周期模型定义的各阶段中过程审核的活动内容、审核依据、审核时机、审核形式且与软件开发计划一致。 | G12: ✓
A13: 6* | B13: 是否完整、准确地列出了本项目软件开发生存周期模型定义的各阶段中产品审核的内容、审核依据、审核时机、审核形式且与软件开发计划一致。 | H13: ✓ | J13: 严重 | K13: 必要内容覆盖不完整
A14: 7 | B14: 是否完整、准确地说明了软件质量保证情况报告的内容、频度和时机。 | G14: ✓
A15: 8 | B15: 是否正确地对软件过程组定义的过程检查单和产品检查单进行了裁剪，且说明了检查单或检查项不适用的原因。 | H15: ✓ | J15: 一般 | K15: 必要内容覆盖不完整
A17: 不符合项问题明细
A18: 问题ID | B18: 检查项 | C18: 问题描述 | F18: 严重程度 | G18: 责任人 | H18: 提交日期 | I18: 计划关闭日期 | J18: 纠正措施 | L18: 关闭
A19: 7 | B19: 6 | C19: 相关工作产品未完整覆盖本检查项要求的必要内容和适用场景，当前结果不能支撑该项要求已经全部落实。 | F19: 严重 | G19: 赵要浦 | H19: 2026-01-06 | I19: 2026-01-07 | J19: 补齐遗漏内容和适用场景，核对相关输入后组织复核，并保留复核结论。 | L19: 否
A20: 8 | B20: 8 | C20: 相关工作产品未完整覆盖本检查项要求的必要内容和适用场景，当前结果不能支撑该项要求已经全部落实。 | F20: 一般 | G20: 赵要浦 | H20: 2026-01-06 | I20: 2026-01-07 | J20: 补齐遗漏内容和适用场景，核对相关输入后组织复核，并保留复核结论。 | L20: 否

Sheet R007-相控阵数字样机软件质量保证计划
B1: 过程/产品审核报告
B2: 编号：ZDPX-03046/0.0-QA-审核报告-007
B3: 项目名称 | D3: 相控阵数字样机软件 | H3: 所处阶段 | J3: 需求分析阶段
B4: 审核对象（过程名称/产品名称） | F4: 相控阵数字样机软件质量保证计划
B5: 审核人 | D5: 高蕾 | F5: 审核日期 | H5: 2026-01-06
B6: 审核依据 | D6: ZDPX-03046/0.0-QA-检查单-007
B7: 本次审核依据《软件质量保证计划检查单》实施。经审核，发现2个不符合项。
B9: NC总数 | D9: 轻微 | F9: 一般 | H9: 严重
B10: =COUNTIF(B13:B14,"<>") | D10: =COUNTIF(F13:F14,"轻微") | F10: =COUNTIF(F13:F14,"一般") | H10: =COUNTIF(F13:F14,"严重")
B11: 不符合项问题（NC）列表
B12: 序号 | C12: 问题描述 | F12: 严重程度 | G12: 责任人 | H12: 提交日期 | I12: 计划关闭日期 | J12: 纠正措施
B13: 1 | C13: ='C007-相控阵数字样机软件质量保证计划'!C19 | F13: ='C007-相控阵数字样机软件质量保证计划'!F19 | G13: ='C007-相控阵数字样机软件质量保证计划'!G19 | H13: ='C007-相控阵数字样机软件质量保证计划'!H19 | I13: ='C007-相控阵数字样机软件质量保证计划'!I19 | J13: ='C007-相控阵数字样机软件质量保证计划'!J19
B14: 2 | C14: ='C007-相控阵数字样机软件质量保证计划'!C20 | F14: ='C007-相控阵数字样机软件质量保证计划'!F20 | G14: ='C007-相控阵数字样机软件质量保证计划'!G20 | H14: ='C007-相控阵数字样机软件质量保证计划'!H20 | I14: ='C007-相控阵数字样机软件质量保证计划'!I20 | J14: ='C007-相控阵数字样机软件质量保证计划'!J20
B16: 纠正措施验证情况：
B17: 已整改并验证通过；已整改并验证通过

Sheet C008-相控阵数字样机软件配置管理计划
A1: 软件配置管理计划检查单
A2: 编号：ZDPX-03046/0.0-QA-检查单-008
A3: 项目名称 | C3: 相控阵数字样机软件 | F3: 当前阶段 | H3: 需求分析阶段 | J3: 项目QA | L3: 高蕾
A4: 审核对象 | C4: 相控阵数字样机软件配置管理计划 | F4: 产品标识 | H4: ZDPX03046/0.0-PGJH | J4: 产品版本 | L4: V1.0
A6: 序号 | B6: 审核内容 | G6: 是 | H6: 否 | I6: 不适用 | J6: 严重程度 | L6: 备注
A7: 通用检查项
A8: 1 | B8: 是否与模板要求一致。 | G8: ✓
A9: 2 | B9: 是否完整、正确地定义了配置管理组织结构 | G9: ✓
A10: 3 | B10: 是否完整、准确地定义了配置管理环境（包括使用工具，配置项存放位置）且与软件开发计划一致。 | G10: ✓
A11: 4* | B11: 是否完整、准确地描述了基线、独立配置项、环境配置项形成的时间点、名称、标识、受控时机。 | G11: ✓
A12: 5* | B12: 描述的软件工作产品是否与软件开发计划一致。 | G12: ✓
A13: 6 | B13: 是否正确地描述了变更控制的方法。 | G13: ✓
A14: 7 | B14: 是否准确地说明了配置状态记实和配置管理报告的时机且与软件开发计划一致。 | G14: ✓
A15: 8 | B15: 是否准确地说明了配置审核的时机和内容且与软件开发计划一致。 | G15: ✓
A16: 9 | B16: 是否准确地说明了配置库备份的时机和方式。 | G16: ✓
A18: 不符合项问题明细
A19: 问题ID | B19: 检查项 | C19: 问题描述 | F19: 严重程度 | G19: 责任人 | H19: 提交日期 | I19: 计划关闭日期 | J19: 纠正措施 | L19: 关闭
A20: 本次审核未发现不符合项。

Sheet R008-相控阵数字样机软件配置管理计划
B1: 过程/产品审核报告
B2: 编号：ZDPX-03046/0.0-QA-审核报告-008
B3: 项目名称 | D3: 相控阵数字样机软件 | H3: 所处阶段 | J3: 需求分析阶段
B4: 审核对象（过程名称/产品名称） | F4: 相控阵数字样机软件配置管理计划
B5: 审核人 | D5: 高蕾 | F5: 审核日期 | H5: 2026-01-06
B6: 审核依据 | D6: ZDPX-03046/0.0-QA-检查单-008
B7: 本次审核依据《软件配置管理计划检查单》实施。经审核，未发现不符合项。
B9: NC总数 | D9: 轻微 | F9: 一般 | H9: 严重
B10: =0 | D10: =0 | F10: =0 | H10: =0
B11: 不符合项问题（NC）列表
B12: 序号 | C12: 问题描述 | F12: 严重程度 | G12: 责任人 | H12: 提交日期 | I12: 计划关闭日期 | J12: 纠正措施
B13: 本次审核未发现不符合项。
B15: 纠正措施验证情况：
B16: 不适用

Sheet C009-审核项目策划过程
A1: 项目策划检查单
A2: 编号：ZDPX-03046/0.0-QA-检查单-009
A3: 项目名称 | C3: 相控阵数字样机软件 | F3: 当前阶段 | H3: 需求分析阶段 | J3: 项目QA | L3: 高蕾
A4: 审核对象 | C4: 审核项目策划过程 | F4: 产品标识 | H4: — | J4: 产品版本 | L4: —
A6: 序号 | B6: 审核内容 | G6: 是 | H6: 否 | I6: 不适用 | J6: 严重程度 | L6: 备注
A7: 通用检查项
A8: 1 | B8: 是否对软件产品进行了标识并记录？ | G8: ✓
A9: 2* | B9: 是否为软件项目选择了生存周期模型，并说明了理由？ | G9: ✓
A10: 3* | B10: 是否对标准过程进行了裁剪，确定了软件项目的过程？ | G10: ✓
A11: 4 | B11: 是否生成工作分解结构并记录？ | G11: ✓
A12: 5 | B12: 是否进行了软件工作产品规模估计？ | G12: ✓
A13: 6 | B13: 是否进行了工作量/成本估计？ | G13: ✓
A14: 7 | B14: 所采用的估计方法是否按正确步骤实施？ | G14: ✓
A15: 8 | B15: 估算结果是否形成了估算报告？ | G15: ✓
A16: 9 | B16: 是否记录了估计的假设数据及假设的依据？ | G16: ✓
A17: 10 | B17: 是否明确并记录了关键路径、任务参与方、利益相关方、资源需求等进度安排依据？ | G17: ✓
A18: 11* | B18: 是否依据估算结果进行了进度安排？ | G18: ✓
A19: 12* | B19: 是否定义了软件项目的里程碑？ | G19: ✓
... A33: 26 | B33: 阶段详细策划的结果是否通知到相关项目组成员，以获得对阶段详细计划的承诺？ | G33: ✓
A35: 不符合项问题明细
A36: 问题ID | B36: 检查项 | C36: 问题描述 | F36: 严重程度 | G36: 责任人 | H36: 提交日期 | I36: 计划关闭日期 | J36: 纠正措施 | L36: 关闭
A37: 本次审核未发现不符合项。

Sheet R009-审核项目策划过程
B1: 过程/产品审核报告
B2: 编号：ZDPX-03046/0.0-QA-审核报告-009
B3: 项目名称 | D3: 相控阵数字样机软件 | H3: 所处阶段 | J3: 需求分析阶段
B4: 审核对象（过程名称/产品名称） | F4: 审核项目策划过程
B5: 审核人 | D5: 高蕾 | F5: 审核日期 | H5: 2026-01-08
B6: 审核依据 | D6: ZDPX-03046/0.0-QA-检查单-009
B7: 本次审核依据《项目策划检查单》实施。经审核，未发现不符合项。
B9: NC总数 | D9: 轻微 | F9: 一般 | H9: 严重
B10: =0 | D10: =0 | F10: =0 | H10: =0
B11: 不符合项问题（NC）列表
B12: 序号 | C12: 问题描述 | F12: 严重程度 | G12: 责任人 | H12: 提交日期 | I12: 计划关闭日期 | J12: 纠正措施
B13: 本次审核未发现不符合项。
B15: 纠正措施验证情况：
B16: 不适用

Sheet C010-审核项目监控过程-双周
A1: 项目监控检查单
A2: 编号：ZDPX-03046/0.0-QA-检查单-010
A3: 项目名称 | C3: 相控阵数字样机软件 | F3: 当前阶段 | H3: 需求分析阶段 | J3: 项目QA | L3: 高蕾
A4: 审核对象 | C4: 审核项目监控过程-双周 | F4: 产品标识 | H4: — | J4: 产品版本 | L4: —
A6: 序号 | B6: 审核内容 | G6: 是 | H6: 否 | I6: 不适用 | J6: 严重程度 | L6: 备注
A7: 通用检查项
A8: 1 | B8: 本阶段的任务是否以任务分配表的形式分配到个人？ | G8: ✓
A9: 2 | B9: 项目组成员是否按时填写个人工作报告，记录个人完成任务的情况、工作量等信息？ | G9: ✓
A10: 3* | B10: 在每个跟踪节点，项目负责人是否对项目进度和工作量进行汇总，并与计划值进行比较？对于超过阈值的偏差是否进行了分析？ | G10: ✓
A11: 4 | B11: 每当工作产品完成时，项目负责人是否统计工作产品实际规模，并与计划值进行比较？对于超过阈值的偏差是否进行了分析？ | G11: ✓
A12: 5 | B12: 是否依据利益相关方参与计划，及时记录利益相关方参与情况？对出现的偏差有无进行分析？ | G12: ✓
A13: 6* | B13: 是否按体系要求对识别出的风险进行跟踪？ | G13: ✓
A14: 7* | B14: 当识别出新风险时，是否更新项目风险表并进行跟踪？ | G14: ✓
A15: 8 | B15: 是否对资源计划进行了跟踪？对出现的偏差有无进行分析？ | G15: ✓
A16: 9 | B16: 是否对培训计划进行了跟踪？对出现的偏差有无进行分析？ | G16: ✓
A17: 10 | B17: 项目负责人对项目跟踪过程中发现的问题是否及时记录，并制定纠正措施？ | G17: ✓
A18: 11 | B18: 纠正措施是否明确了责任人、验证人？ | G18: ✓
A19: 12* | B19: 当纠正措施会影响到对外承诺时，是否与利益相关方对纠正措施进行了评审？ | G19: ✓
... A25: 18 | B25: 是否定期（阶段末和里程碑）对需求管理工作进行总结，形成需求管理情况工作报告？ | G25: ✓
A26: 19* | B26: 项目负责人是否定期（双周、阶段末和里程碑）将工作进展及策划参数跟踪情况、问题及风险跟踪情况、偏差处理措施等进行汇总，形成项目进展报告？ | H26: ✓ | J26: 严重 | K26: 必要内容覆盖不完整
A27: 20 | B27: 项目进展报告是否上报给项目总监，并通报给项目组人员？ | G27: ✓
A28: 21 | B28: 项目例会中是否对进展报告进行了交流，并对问题、风险、偏差等进行了讨论？ | G28: ✓
A29: 22 | B29: 项目例会有无形成会议纪要？ | G29: ✓
A30: 23* | B30: 是否按计划实施里程碑评审？ | G30: ✓
A31: 24 | B31: 里程碑评审参会人员是否符合体系要求？ | G31: ✓
A32: 25* | B32: 里程碑评审会的材料是否准备齐全？ | G32: ✓
A33: 26 | B33: 里程碑评审是否对评审节点前的项目进展情况、规模、进度、工作量、问题和风险等的跟踪情况进行了分析并标识出偏差。 | G33: ✓
A34: 27 | B34: 对于超出阈值的偏差是否分析了原因，并提出相应的措施 | G34: ✓
A35: 28 | B35: 是否对新识别的问题制定了纠正措施 | G35: ✓
A36: 29* | B36: 里程碑评审后是否形成评审报告，并指定负责人处理评审意见。 | G36: ✓
A37: 30 | B37: 对评审意见的处理有无进行跟踪，直到形成闭环 | G37: ✓
A38: 31 | B38: 需对软件开发计划进行变更时，是否按要求办理了变更审批手续 | G38: ✓
... A41: 34 | B41: 是否有通知受影响的组和个人的记录 | G41: ✓
A43: 不符合项问题明细
A44: 问题ID | B44: 检查项 | C44: 问题描述 | F44: 严重程度 | G44: 责任人 | H44: 提交日期 | I44: 计划关闭日期 | J44: 纠正措施 | L44: 关闭
A45: 9 | B45: 19 | C45: 相关工作产品未完整覆盖本检查项要求的必要内容和适用场景，当前结果不能支撑该项要求已经全部落实。 | F45: 严重 | G45: 赵要浦 | H45: 2026-01-12 | I45: 2026-01-12 | J45: 补齐遗漏内容和适用场景，核对相关输入后组织复核，并保留复核结论。 | L45: 否

Sheet R010-审核项目监控过程-双周
B1: 过程/产品审核报告
B2: 编号：ZDPX-03046/0.0-QA-审核报告-010
B3: 项目名称 | D3: 相控阵数字样机软件 | H3: 所处阶段 | J3: 需求分析阶段
B4: 审核对象（过程名称/产品名称） | F4: 审核项目监控过程-双周
B5: 审核人 | D5: 高蕾 | F5: 审核日期 | H5: 2026-01-12
B6: 审核依据 | D6: ZDPX-03046/0.0-QA-检查单-010
B7: 本次审核依据《项目监控检查单》实施。经审核，发现1个不符合项。
B9: NC总数 | D9: 轻微 | F9: 一般 | H9: 严重
B10: =COUNTIF(B13:B13,"<>") | D10: =COUNTIF(F13:F13,"轻微") | F10: =COUNTIF(F13:F13,"一般") | H10: =COUNTIF(F13:F13,"严重")
B11: 不符合项问题（NC）列表
B12: 序号 | C12: 问题描述 | F12: 严重程度 | G12: 责任人 | H12: 提交日期 | I12: 计划关闭日期 | J12: 纠正措施
B13: 1 | C13: ='C010-审核项目监控过程-双周'!C45 | F13: ='C010-审核项目监控过程-双周'!F45 | G13: ='C010-审核项目监控过程-双周'!G45 | H13: ='C010-审核项目监控过程-双周'!H45 | I13: ='C010-审核项目监控过程-双周'!I45 | J13: ='C010-审核项目监控过程-双周'!J45
B15: 纠正措施验证情况：
B16: 已整改并验证通过

Sheet C011-审核测量与绩效管理过程-双周
A1: 测量与绩效管理检查单
A2: 编号：ZDPX-03046/0.0-QA-检查单-011
A3: 项目名称 | C3: 相控阵数字样机软件 | F3: 当前阶段 | H3: 需求分析阶段 | J3: 项目QA | L3: 高蕾
A4: 审核对象 | C4: 审核测量与绩效管理过程-双周 | F4: 产品标识 | H4: — | J4: 产品版本 | L4: —
A6: 序号 | B6: 审核内容 | G6: 是 | H6: 否 | I6: 不适用 | J6: 严重程度 | L6: 备注
A7: 通用检查项
A8: 1* | B8: 是否建立了项目的测量目标？ | H8: ✓ | J8: 严重 | K8: 必要内容覆盖不完整
A9: 2 | B9: 是否根据测量目标确定了项目所要使用的测量项？ | G9: ✓
A10: 3 | B10: 是否指定了测量分析的负责人？ | G10: ✓
A11: 4 | B11: 是否确定了测量数据的存储方式？ | H11: ✓ | J11: 一般 | K11: 必要内容覆盖不完整
A12: 5 | B12: 是否明确了项目测量项的采集时机、采集方法、采集位置及采集人？ | G12: ✓
A13: 6 | B13: 是否指明了对测量数据的分析方法、表达方式等？ | G13: ✓
A14: 7 | B14: 是否明确了测量数据分析结果的交流时机、交流方式？ | G14: ✓
A15: 8 | B15: 是否制定了项目的测量与分析计划？并对测量分析计划进行了评审？ | G15: ✓
A16: 9 | B16: 当项目有新增测量项时，是否经过软件工程过程组的审批？ | G16: ✓
A17: 10 | B17: 是否按照测量与分析计划，在规定的时间和采集点收集测量数据？ | G17: ✓
A18: 11 | B18: 是否将采集到的数据（需要时进行预处理）存入指定的数据分析工具平台？ | G18: ✓
A19: 12 | B19: 是否在计划时间点对采集到的测量数据进行分析？ | G19: ✓
A20: 13 | B20: 是否将分析结果汇总形成测量与分析报告？ | G20: ✓
A21: 14 | B21: 是否与项目组、利益相关方（必要时）交流了测量数据的分析结果？ | G21: ✓
A22: 15 | B22: 项目实施过程中，测量相关的数据和文档有无得到有效控制？ | G22: ✓
A24: 不符合项问题明细
A25: 问题ID | B25: 检查项 | C25: 问题描述 | F25: 严重程度 | G25: 责任人 | H25: 提交日期 | I25: 计划关闭日期 | J25: 纠正措施 | L25: 关闭
A26: 10 | B26: 1 | C26: 相关工作产品未完整覆盖本检查项要求的必要内容和适用场景，当前结果不能支撑该项要求已经全部落实。 | F26: 严重 | G26: 赵要浦 | H26: 2026-01-12 | I26: 2026-01-12 | J26: 补齐遗漏内容和适用场景，核对相关输入后组织复核，并保留复核结论。 | L26: 否
A27: 11 | B27: 4 | C27: 相关工作产品未完整覆盖本检查项要求的必要内容和适用场景，当前结果不能支撑该项要求已经全部落实。 | F27: 一般 | G27: 赵要浦 | H27: 2026-01-12 | I27: 2026-01-12 | J27: 补齐遗漏内容和适用场景，核对相关输入后组织复核，并保留复核结论。 | L27: 否

Sheet R011-审核测量与绩效管理过程-双周
B1: 过程/产品审核报告
B2: 编号：ZDPX-03046/0.0-QA-审核报告-011
B3: 项目名称 | D3: 相控阵数字样机软件 | H3: 所处阶段 | J3: 需求分析阶段
B4: 审核对象（过程名称/产品名称） | F4: 审核测量与绩效管理过程-双周
B5: 审核人 | D5: 高蕾 | F5: 审核日期 | H5: 2026-01-12
B6: 审核依据 | D6: ZDPX-03046/0.0-QA-检查单-011
B7: 本次审核依据《测量与绩效管理检查单》实施。经审核，发现2个不符合项。
B9: NC总数 | D9: 轻微 | F9: 一般 | H9: 严重
B10: =COUNTIF(B13:B14,"<>") | D10: =COUNTIF(F13:F14,"轻微") | F10: =COUNTIF(F13:F14,"一般") | H10: =COUNTIF(F13:F14,"严重")
B11: 不符合项问题（NC）列表
B12: 序号 | C12: 问题描述 | F12: 严重程度 | G12: 责任人 | H12: 提交日期 | I12: 计划关闭日期 | J12: 纠正措施
B13: 1 | C13: ='C011-审核测量与绩效管理过程-双周'!C26 | F13: ='C011-审核测量与绩效管理过程-双周'!F26 | G13: ='C011-审核测量与绩效管理过程-双周'!G26 | H13: ='C011-审核测量与绩效管理过程-双周'!H26 | I13: ='C011-审核测量与绩效管理过程-双周'!I26 | J13: ='C011-审核测量与绩效管理过程-双周'!J26
B14: 2 | C14: ='C011-审核测量与绩效管理过程-双周'!C27 | F14: ='C011-审核测量与绩效管理过程-双周'!F27 | G14: ='C011-审核测量与绩效管理过程-双周'!G27 | H14: ='C011-审核测量与绩效管理过程-双周'!H27 | I14: ='C011-审核测量与绩效管理过程-双周'!I27 | J14: ='C011-审核测量与绩效管理过程-双周'!J27
B16: 纠正措施验证情况：
B17: 已整改并验证通过；已整改并验证通过

Sheet C012-相控阵数字样机软件需求规格说明
A1: 软件需求规格说明检查单
A2: 编号：ZDPX-03046/0.0-QA-检查单-012
A3: 项目名称 | C3: 相控阵数字样机软件 | F3: 当前阶段 | H3: 需求分析阶段 | J3: 项目QA | L3: 高蕾
A4: 审核对象 | C4: 相控阵数字样机软件需求规格说明 | F4: 产品标识 | H4: ZDPX03046/0.0-RJXG | J4: 产品版本 | L4: V1.0
A6: 序号 | B6: 审核内容 | G6: 是 | H6: 否 | I6: 不适用 | J6: 严重程度 | L6: 备注
A7: 通用检查项
A8: 1 | B8: 是否符合有关模板的格式要求。 | G8: ✓
A9: 2* | B9: 需求描述是否清晰准确？各个需求之间是否存在冲突和矛盾，同一需求的描述是否始终一致。 | G9: ✓
A10: 3 | B10: 是否明确定义了对外接口关系及接口内容？ | G10: ✓
A11: 4 | B11: 是否明确定义了内部接口关系及接口内容？ | G11: ✓
A12: 5 | B12: 是否明确定义了软件内部所有数据元素（包括数据库和数据文件）的需求？ | G12: ✓
A13: 6* | B13: 所有技术需求是否都具备可测试性？ | G13: ✓
A14: 7 | B14: 是否准确说明CSCI适应性要求（即在进行安装和运行时系统环境变量参数要求）？ | G14: ✓
A15: 8* | B15: 是否正确描述了安全性要求，且合理可行和可验证？ | H15: ✓ | J15: 严重 | K15: 必要内容覆盖不完整
A16: 9* | B16: 是否正确描述了保密性要求，且合理可行和可验证？ | G16: ✓
A17: 10* | B17: 是否完整、准确描述软件运行的计算机硬件和操作系统等环境需求且与软件研制任务书的要求一致? | G17: ✓
A18: 11* | B18: 是否准确描述了软件研制任务书中对软件质量方面的要求（如：软件的功能性、可靠性、可维护性、可用性、灵活性、可移植性、可重用性、可测试性、易用性）且合理可行和可验证? | G18: ✓
A19: 12 | B19: 是否正确说明了CSCI对人员因素的工程需求（人的能力、限制、人为错误、环境影响）？ | G19: ✓
A20: 13 | B20: 是否正确地提出了为用户提供的软件培训的需求？ | G20: ✓
A21: 14 | B21: 是否准确说明了有关软件交付用户方面的要求？ | G21: ✓
A22: 15 | B22: 是否说明了软件介质的标识、封装、防震等包装方面需？ | G22: ✓
A23: 16 | B23: 是否明确定义了软件的安全关键等级? | G23: ✓
A24: 17 | B24: 是否完整、准确地说明了已定义的软件需求的合格性审查方法？ | H24: ✓ | J24: 一般 | K24: 必要内容覆盖不完整
A25: 18* | B25: 软件设计约束条件是否与软件研制任务书一致？ | G25: ✓
A26: 19* | B26: 是否完整、准确地建立了已定义的CSCI需求与上级需求的映射关系，建立需求跟踪表？ | G26: ✓
A28: 不符合项问题明细
A29: 问题ID | B29: 检查项 | C29: 问题描述 | F29: 严重程度 | G29: 责任人 | H29: 提交日期 | I29: 计划关闭日期 | J29: 纠正措施 | L29: 关闭
A30: 12 | B30: 8 | C30: 相关工作产品未完整覆盖本检查项要求的必要内容和适用场景，当前结果不能支撑该项要求已经全部落实。 | F30: 严重 | G30: 赵要浦 | H30: 2026-01-15 | I30: 2026-01-16 | J30: 补齐遗漏内容和适用场景，核对相关输入后组织复核，并保留复核结论。 | L30: 否
A31: 13 | B31: 17 | C31: 相关工作产品未完整覆盖本检查项要求的必要内容和适用场景，当前结果不能支撑该项要求已经全部落实。 | F31: 一般 | G31: 赵要浦 | H31: 2026-01-15 | I31: 2026-01-16 | J31: 补齐遗漏内容和适用场景，核对相关输入后组织复核，并保留复核结论。 | L31: 否

Sheet R012-相控阵数字样机软件需求规格说明
B1: 过程/产品审核报告
B2: 编号：ZDPX-03046/0.0-QA-审核报告-012
B3: 项目名称 | D3: 相控阵数字样机软件 | H3: 所处阶段 | J3: 需求分析阶段
B4: 审核对象（过程名称/产品名称） | F4: 相控阵数字样机软件需求规格说明
B5: 审核人 | D5: 高蕾 | F5: 审核日期 | H5: 2026-01-15
B6: 审核依据 | D6: ZDPX-03046/0.0-QA-检查单-012
B7: 本次审核依据《软件需求规格说明检查单》实施。经审核，发现2个不符合项。
B9: NC总数 | D9: 轻微 | F9: 一般 | H9: 严重
B10: =COUNTIF(B13:B14,"<>") | D10: =COUNTIF(F13:F14,"轻微") | F10: =COUNTIF(F13:F14,"一般") | H10: =COUNTIF(F13:F14,"严重")
B11: 不符合项问题（NC）列表
B12: 序号 | C12: 问题描述 | F12: 严重程度 | G12: 责任人 | H12: 提交日期 | I12: 计划关闭日期 | J12: 纠正措施
B13: 1 | C13: ='C012-相控阵数字样机软件需求规格说明'!C30 | F13: ='C012-相控阵数字样机软件需求规格说明'!F30 | G13: ='C012-相控阵数字样机软件需求规格说明'!G30 | H13: ='C012-相控阵数字样机软件需求规格说明'!H30 | I13: ='C012-相控阵数字样机软件需求规格说明'!I30 | J13: ='C012-相控阵数字样机软件需求规格说明'!J30
B14: 2 | C14: ='C012-相控阵数字样机软件需求规格说明'!C31 | F14: ='C012-相控阵数字样机软件需求规格说明'!F31 | G14: ='C012-相控阵数字样机软件需求规格说明'!G31 | H14: ='C012-相控阵数字样机软件需求规格说明'!H31 | I14: ='C012-相控阵数字样机软件需求规格说明'!I31 | J14: ='C012-相控阵数字样机软件需求规格说明'!J31
B16: 纠正措施验证情况：
B17: 已整改并验证通过；已整改并验证通过

Sheet C013-相控阵数字样机软件测试计划
A1: 软件测试计划检查单
A2: 编号：ZDPX-03046/0.0-QA-检查单-013
A3: 项目名称 | C3: 相控阵数字样机软件 | F3: 当前阶段 | H3: 需求分析阶段 | J3: 项目QA | L3: 高蕾
A4: 审核对象 | C4: 相控阵数字样机软件测试计划 | F4: 产品标识 | H4: ZDPX03046/0.0-HCJH | J4: 产品版本 | L4: V1.0
A6: 序号 | B6: 审核内容 | G6: 是 | H6: 否 | I6: 不适用 | J6: 严重程度 | L6: 备注
A7: 通用检查项
A8: 1 | B8: 是否符合有关模板的格式要求？ | H8: ✓ | J8: 一般 | K8: 必要内容覆盖不完整
A9: 2* | B9: 是否定义了测试范围和测试内容？ | G9: ✓
A10: 3 | B10: 是否描述了测试环境，包括所需的软件和硬件？ | G10: ✓
A11: 4 | B11: 是否明确了测试活动级别（单元测试、集成测试、合格性测试）且与软件开发计划的要求一致？ | G11: ✓
A12: 5 | B12: 是否明确要执行的测试类别（功能测试、健壮性测试、接口测试、性能测试和安装测试）且合理可行？ | G12: ✓
A13: 6 | B13: 是否明确了总体测试要求（每个测试的输入、功能点的测试覆盖率达到100%）且合理可行？ | G13: ✓
A14: 7 | B14: 是否有测试内容记录要求？ | H14: ✓ | J14: 一般 | K14: 必要内容覆盖不完整
A15: 8 | B15: 是否完整、准确地说明了测试进度计划且与软件开发计划的要求一致？ | G15: ✓
A16: 9 | B16: 是否明确了参加测试活动的组织和职责、参加人员？ | G16: ✓
A17: 10* | B17: 测试项设计是否覆盖需求文档中的可测试的技术需求？ | G17: ✓
A19: 不符合项问题明细
A20: 问题ID | B20: 检查项 | C20: 问题描述 | F20: 严重程度 | G20: 责任人 | H20: 提交日期 | I20: 计划关闭日期 | J20: 纠正措施 | L20: 关闭
A21: 14 | B21: 1 | C21: 相关工作产品未完整覆盖本检查项要求的必要内容和适用场景，当前结果不能支撑该项要求已经全部落实。 | F21: 一般 | G21: 赵要浦 | H21: 2026-01-21 | I21: 2026-01-22 | J21: 补齐遗漏内容和适用场景，核对相关输入后组织复核，并保留复核结论。 | L21: 否
A22: 15 | B22: 7 | C22: 相关工作产品未完整覆盖本检查项要求的必要内容和适用场景，当前结果不能支撑该项要求已经全部落实。 | F22: 一般 | G22: 赵要浦 | H22: 2026-01-21 | I22: 2026-01-22 | J22: 补齐遗漏内容和适用场景，核对相关输入后组织复核，并保留复核结论。 | L22: 否

Sheet R013-相控阵数字样机软件测试计划
B1: 过程/产品审核报告
B2: 编号：ZDPX-03046/0.0-QA-审核报告-013
B3: 项目名称 | D3: 相控阵数字样机软件 | H3: 所处阶段 | J3: 需求分析阶段
B4: 审核对象（过程名称/产品名称） | F4: 相控阵数字样机软件测试计划
B5: 审核人 | D5: 高蕾 | F5: 审核日期 | H5: 2026-01-21
B6: 审核依据 | D6: ZDPX-03046/0.0-QA-检查单-013
B7: 本次审核依据《软件测试计划检查单》实施。经审核，发现2个不符合项。
B9: NC总数 | D9: 轻微 | F9: 一般 | H9: 严重
B10: =COUNTIF(B13:B14,"<>") | D10: =COUNTIF(F13:F14,"轻微") | F10: =COUNTIF(F13:F14,"一般") | H10: =COUNTIF(F13:F14,"严重")
B11: 不符合项问题（NC）列表
B12: 序号 | C12: 问题描述 | F12: 严重程度 | G12: 责任人 | H12: 提交日期 | I12: 计划关闭日期 | J12: 纠正措施
B13: 1 | C13: ='C013-相控阵数字样机软件测试计划'!C21 | F13: ='C013-相控阵数字样机软件测试计划'!F21 | G13: ='C013-相控阵数字样机软件测试计划'!G21 | H13: ='C013-相控阵数字样机软件测试计划'!H21 | I13: ='C013-相控阵数字样机软件测试计划'!I21 | J13: ='C013-相控阵数字样机软件测试计划'!J21
B14: 2 | C14: ='C013-相控阵数字样机软件测试计划'!C22 | F14: ='C013-相控阵数字样机软件测试计划'!F22 | G14: ='C013-相控阵数字样机软件测试计划'!G22 | H14: ='C013-相控阵数字样机软件测试计划'!H22 | I14: ='C013-相控阵数字样机软件测试计划'!I22 | J14: ='C013-相控阵数字样机软件测试计划'!J22
B16: 纠正措施验证情况：
B17: 已整改并验证通过；已整改并验证通过

Sheet C014-审核验证与确认过程
A1: 验证与确认检查单
A2: 编号：ZDPX-03046/0.0-QA-检查单-014
A3: 项目名称 | C3: 相控阵数字样机软件 | F3: 当前阶段 | H3: 需求分析阶段 | J3: 项目QA | L3: 高蕾
A4: 审核对象 | C4: 审核验证与确认过程 | F4: 产品标识 | H4: — | J4: 产品版本 | L4: —
A6: 序号 | B6: 审核内容 | G6: 是 | H6: 否 | I6: 不适用 | J6: 严重程度 | L6: 备注
A7: 通用检查项
A8: 1* | B8: 有无按计划对本阶段工作产品实施验证与确认活动？ | G8: ✓
A9: 工作产品评审过程
A10: 1 | B10: 项目策划时有无制定评审计划，对评审形式、评审对象和评审时机进行明确？ | G10: ✓
A11: 2 | B11: 提交评审的文档是否经过项目QA的产品审核？ | G11: ✓
A12: 3 | B12: 评审前是否基于检查单模板准备了评审检查单？ | G12: ✓
A13: 4 | B13: 若评审检查单的检查项有修改时，是否经过EPG组的审批？ | G13: ✓
A14: 5 | B14: 参加评审的人员是否符合要求(依据相关过程文件规定) | G14: ✓
A15: 6 | B15: 评审是否采取了正确的形式？（会议或审签） | G15: ✓
A16: 7* | B16: 是否记录了评审中发现的缺陷，并按要求形成了评审报告？ | G16: ✓
A17: 8 | B17: 对于评审中发现的缺陷，是否指定了负责修改人？ | G17: ✓
A18: 9 | B18: 是否指定了负责人对评审缺陷的处理情况进行跟踪和验证？是否有跟踪验证的记录？ | G18: ✓
A19: 10* | B19: 评审缺陷是否归零？ | G19: ✓
A20: 测试过程
A21: 1 | B21: 对于测试活动，有无制定测试计划，对测试方法、所需资源、测试对象和范围、测试进度安排进行明确？ | G21: ✓
A22: 2 | B22: 测试计划有无经过评审？ | G22: ✓
A23: 3 | B23: 实施测试前，有无建立测试规程对测试环境、运行场景、输入输出、实施步骤、准入准则、通过准则等予以文档化说明？ | G23: ✓
A24: 4 | B24: 对测试环境有无开展与目标环境的差异性分析？ | G24: ✓
A25: 5* | B25: 测试规程有无经过评审？ | G25: ✓
A26: 6* | B26: 实施测试前有无进行测试就绪状态确认？ | G26: ✓
A27: 7* | B27: 有无如实记录测试用例执行过程？对于有量值要求的指标，有无记录实测值？ | H27: ✓ | J27: 严重 | K27: 必要内容覆盖不完整
A28: 8 | B28: 对于测试发现的缺陷有无进行标识、记录并形成问题报告单？ | H28: ✓ | J28: 一般 | K28: 必要内容覆盖不完整
A29: 9 | B29: 对于测试缺陷，有无分析并确定原因，并制定纠正措施？ | G29: ✓
A30: 10 | B30: 对属于测试方法、准则及环境等因素的缺陷，有无修订测试规程并重新进行测试？ | G30: ✓
A31: 11 | B31: 对处理后的测试缺陷有无进行回归测试？ | G31: ✓
A32: 12* | B32: 对测试结果有无进行分析总结形成测试报告，并和利益相关方进行沟通确认？ | G32: ✓
A33: 13* | B33: 测试报告有无经过评审？ | G33: ✓
A34: 14* | B34: 测试缺陷有无归零？如未归零，有无明确的放行标准？ | G34: ✓
A36: 不符合项问题明细
A37: 问题ID | B37: 检查项 | C37: 问题描述 | F37: 严重程度 | G37: 责任人 | H37: 提交日期 | I37: 计划关闭日期 | J37: 纠正措施 | L37: 关闭
A38: 16 | B38: 7 | C38: 相关工作产品未完整覆盖本检查项要求的必要内容和适用场景，当前结果不能支撑该项要求已经全部落实。 | F38: 严重 | G38: 赵要浦 | H38: 2026-01-23 | I38: 2026-01-23 | J38: 补齐遗漏内容和适用场景，核对相关输入后组织复核，并保留复核结论。 | L38: 否
A39: 17 | B39: 8 | C39: 相关工作产品未完整覆盖本检查项要求的必要内容和适用场景，当前结果不能支撑该项要求已经全部落实。 | F39: 一般 | G39: 赵要浦 | H39: 2026-01-23 | I39: 2026-01-23 | J39: 补齐遗漏内容和适用场景，核对相关输入后组织复核，并保留复核结论。 | L39: 否

Sheet R014-审核验证与确认过程
B1: 过程/产品审核报告
B2: 编号：ZDPX-03046/0.0-QA-审核报告-014
B3: 项目名称 | D3: 相控阵数字样机软件 | H3: 所处阶段 | J3: 需求分析阶段
B4: 审核对象（过程名称/产品名称） | F4: 审核验证与确认过程
B5: 审核人 | D5: 高蕾 | F5: 审核日期 | H5: 2026-01-23
B6: 审核依据 | D6: ZDPX-03046/0.0-QA-检查单-014
B7: 本次审核依据《验证与确认检查单》实施。经审核，发现2个不符合项。
B9: NC总数 | D9: 轻微 | F9: 一般 | H9: 严重
B10: =COUNTIF(B13:B14,"<>") | D10: =COUNTIF(F13:F14,"轻微") | F10: =COUNTIF(F13:F14,"一般") | H10: =COUNTIF(F13:F14,"严重")
B11: 不符合项问题（NC）列表
B12: 序号 | C12: 问题描述 | F12: 严重程度 | G12: 责任人 | H12: 提交日期 | I12: 计划关闭日期 | J12: 纠正措施
B13: 1 | C13: ='C014-审核验证与确认过程'!C38 | F13: ='C014-审核验证与确认过程'!F38 | G13: ='C014-审核验证与确认过程'!G38 | H13: ='C014-审核验证与确认过程'!H38 | I13: ='C014-审核验证与确认过程'!I38 | J13: ='C014-审核验证与确认过程'!J38
B14: 2 | C14: ='C014-审核验证与确认过程'!C39 | F14: ='C014-审核验证与确认过程'!F39 | G14: ='C014-审核验证与确认过程'!G39 | H14: ='C014-审核验证与确认过程'!H39 | I14: ='C014-审核验证与确认过程'!I39 | J14: ='C014-审核验证与确认过程'!J39
B16: 纠正措施验证情况：
B17: 已整改并验证通过；已整改并验证通过

Sheet C015-审核需求开发与管理过程
A1: 需求开发与管理检查单
A2: 编号：ZDPX-03046/0.0-QA-检查单-015
A3: 项目名称 | C3: 相控阵数字样机软件 | F3: 当前阶段 | H3: 需求分析阶段 | J3: 项目QA | L3: 高蕾
A4: 审核对象 | C4: 审核需求开发与管理过程 | F4: 产品标识 | H4: — | J4: 产品版本 | L4: —
A6: 序号 | B6: 审核内容 | G6: 是 | H6: 否 | I6: 不适用 | J6: 严重程度 | L6: 备注
A7: 需求开发与确认
A8: 1* | B8: 是否对顾客需求进行了开发并编制了顾客需求文档？（技术协议、软件研制任务书初稿、顾客需求列表等） | G8: ✓
A9: 2* | B9: 是否明确了本项目的需求提供者？ | G9: ✓
A10: 3 | B10: 对文档化的初始顾客需求，是否组织了需求研讨？ （软件研制任务书的研讨、技术协议的研讨等） | G10: ✓
A11: 4 | B11: 需求提供者及其他利益相关方有无参加顾客需求研讨？研讨活动有无留存记录？ | G11: ✓
A12: 5* | B12: 需求提供者、利益相关方和项目参与者对顾客需求有无达成共识？项目参与者对顾客需求有无作出承诺？（软件研制任务书的评审、合同流转签署等） | G12: ✓
A13: 6* | B13: 有无对系统或软件的运行方案和场景进行开发和定义，并体现在相应的文档中？（系统规格、软件需规、技术方案、运行方案等） | G13: ✓
A14: 7* | B14: 有无和利益相关方一起对运行方案和场景进行评审？ | G14: ✓
A15: 8 | B15: 产品和产品部件需求开发是否以顾客需求或系统分配需求（功能基线）作为输入？ | G15: ✓
A16: 9 | B16: 对产品和产品部件需求的开发，除功能需求外，有无包含性能、接口、可靠性、安全性等非功能需求的开发？ | G16: ✓
A17: 10 | B17: 产品和产品部件需求开发的结果是否文档化？（系统规格、软件需规） | G17: ✓
A18: 11* | B18: 有无对需求的必要性和充分性进行分析，并与利益相关方一起确认需求？（系统规格、软件需规的评审） | G18: ✓
A19: 12* | B19: 是否以通过评审、批准的软件需求规格说明作为软件设计的依据？ | G19: ✓
... A23: 16* | B23: 源代码是否通过了各级测试？ | G23: ✓
A24: 需求管理
A25: 17* | B25: 软件研制任务书评审通过后，是否建立了功能基线？ | G25: ✓
A26: 18* | B26: 软件需规评审通过后，是否建立了分配基线？ | G26: ✓
A27: 19* | B27: 是否按照体系规定的追踪关系，在生成的各文档中都填写了正向和逆向追踪表。 | H27: ✓ | J27: 严重 | K27: 必要内容覆盖不完整
A28: 20 | B28: 项目负责人发现需求管理问题时，是否依据《项目监控过程》的要求填写了“项目问题跟踪表”。 | G28: ✓
A29: 21 | B29: 发现的需求管理问题是否在项目工作例会上通报，并跟踪直至问题关闭。 | H29: ✓ | J29: 一般 | K29: 必要内容覆盖不完整
A30: 22 | B30: 项目负责人是否在项目阶段总结、里程碑评审前形成需求管理情况工作报告？ | G30: ✓
A31: 23* | B31: 顾客需求的变更是否得到合同甲方或用户的认可？ | G31: ✓
A32: 24* | B32: 需求发生变更时，是否填写了变更申请单，说明了需变更的内容并进行了影响域分析？ | G32: ✓
A33: 25* | B33: 变更申请是否经过了评估，并得到了批准？批准的权限是否正确？ | G33: ✓
A34: 26 | B34: 需求发生变更时，是否更新了受影响的各项工作产品？ | G34: ✓
A35: 27 | B35: 需求变更完成后，是否通过评审、测试等方式对变更情况进行确认，并填写了变更报告 | G35: ✓
A36: 28 | B36: 需求变更完成后是否更新了受控库中的功能基线或分配基线并发布？ | G36: ✓
A37: 29* | B37: 当变更影响对外承诺时，是否由公司软件配置控制委员会进行了审批？ | G37: ✓
A39: 不符合项问题明细
A40: 问题ID | B40: 检查项 | C40: 问题描述 | F40: 严重程度 | G40: 责任人 | H40: 提交日期 | I40: 计划关闭日期 | J40: 纠正措施 | L40: 关闭
A41: 18 | B41: 19 | C41: 相关工作产品未完整覆盖本检查项要求的必要内容和适用场景，当前结果不能支撑该项要求已经全部落实。 | F41: 严重 | G41: 赵要浦 | H41: 2026-01-23 | I41: 2026-01-23 | J41: 补齐遗漏内容和适用场景，核对相关输入后组织复核，并保留复核结论。 | L41: 否
A42: 19 | B42: 21 | C42: 相关工作产品未完整覆盖本检查项要求的必要内容和适用场景，当前结果不能支撑该项要求已经全部落实。 | F42: 一般 | G42: 赵要浦 | H42: 2026-01-23 | I42: 2026-01-23 | J42: 补齐遗漏内容和适用场景，核对相关输入后组织复核，并保留复核结论。 | L42: 否

Sheet R015-审核需求开发与管理过程
B1: 过程/产品审核报告
B2: 编号：ZDPX-03046/0.0-QA-审核报告-015
B3: 项目名称 | D3: 相控阵数字样机软件 | H3: 所处阶段 | J3: 需求分析阶段
B4: 审核对象（过程名称/产品名称） | F4: 审核需求开发与管理过程
B5: 审核人 | D5: 高蕾 | F5: 审核日期 | H5: 2026-01-23
B6: 审核依据 | D6: ZDPX-03046/0.0-QA-检查单-015
B7: 本次审核依据《需求开发与管理检查单》实施。经审核，发现2个不符合项。
B9: NC总数 | D9: 轻微 | F9: 一般 | H9: 严重
B10: =COUNTIF(B13:B14,"<>") | D10: =COUNTIF(F13:F14,"轻微") | F10: =COUNTIF(F13:F14,"一般") | H10: =COUNTIF(F13:F14,"严重")
B11: 不符合项问题（NC）列表
B12: 序号 | C12: 问题描述 | F12: 严重程度 | G12: 责任人 | H12: 提交日期 | I12: 计划关闭日期 | J12: 纠正措施
B13: 1 | C13: ='C015-审核需求开发与管理过程'!C41 | F13: ='C015-审核需求开发与管理过程'!F41 | G13: ='C015-审核需求开发与管理过程'!G41 | H13: ='C015-审核需求开发与管理过程'!H41 | I13: ='C015-审核需求开发与管理过程'!I41 | J13: ='C015-审核需求开发与管理过程'!J41
B14: 2 | C14: ='C015-审核需求开发与管理过程'!C42 | F14: ='C015-审核需求开发与管理过程'!F42 | G14: ='C015-审核需求开发与管理过程'!G42 | H14: ='C015-审核需求开发与管理过程'!H42 | I14: ='C015-审核需求开发与管理过程'!I42 | J14: ='C015-审核需求开发与管理过程'!J42
B16: 纠正措施验证情况：
B17: 已整改并验证通过；已整改并验证通过

Sheet C016-审核配置管理过程-阶段
A1: 配 置 管 理 检 查 单
A2: 编号：ZDPX-03046/0.0-QA-检查单-016
A3: 项目名称 | C3: 相控阵数字样机软件 | F3: 当前阶段 | H3: 需求分析阶段 | J3: 项目QA | L3: 高蕾
A4: 审核对象 | C4: 审核配置管理过程-阶段 | F4: 产品标识 | H4: — | J4: 产品版本 | L4: —
A6: 序号 | B6: 审核内容 | G6: 是 | H6: 否 | I6: 不适用 | J6: 严重程度 | L6: 备注
A7: 通用检查项
A8: 1 | B8: 是否为项目建立了受控库和开发库？ | H8: ✓ | J8: 一般 | K8: 必要内容覆盖不完整
A9: 2* | B9: 是否按计划对配置项进行了受控管理？ | G9: ✓
A10: 3 | B10: 配置项的出入库单填写是否正确？ | G10: ✓
A11: 4 | B11: 受控库中配置项和基线的标识是否遵循了标识规则？ | G11: ✓
A12: 5* | B12: 受控库中基线的组成配置项是否与配置管理计划一致？ | G12: ✓
A13: 6 | B13: 受控库中每个基线版本是否都对应基线发布单？ | G13: ✓
A14: 7 | B14: 基线的建立和和变更情况是否通报给所有受影响的组和个人？ | G14: ✓
A15: 8 | B15: 配置项出入库、基线发布是否都经过了正确的审批？ | G15: ✓
A16: 9 | B16: 受控库是否按配置管理计划中的备份策略进行了备份？ | G16: ✓
A17: 10 | B17: 开发库的使用与配置管理计划要求是否一致？ | G17: ✓
A18: 11 | B18: 环境配置项有无受控管理？ | G18: ✓
A19: 12* | B19: 提交变更申请时，是否具体描述了需变更的内容，并进行了影响域分析？ | G19: ✓
A20: 13* | B20: 变更影响域分析是否识别出可能涉及到的相关配置项？ | G20: ✓
... A28: 21 | B28: 是否按规定生成了阶段或里程碑配置管理报告 | G28: ✓
A29: 22 | B29: 配置管理报告内容是否完整 | H29: ✓ | J29: 一般 | K29: 必要内容覆盖不完整
A31: 不符合项问题明细
A32: 问题ID | B32: 检查项 | C32: 问题描述 | F32: 严重程度 | G32: 责任人 | H32: 提交日期 | I32: 计划关闭日期 | J32: 纠正措施 | L32: 关闭
A33: 20 | B33: 1 | C33: 相关工作产品未完整覆盖本检查项要求的必要内容和适用场景，当前结果不能支撑该项要求已经全部落实。 | F33: 一般 | G33: 赵要浦 | H33: 2026-01-23 | I33: 2026-01-23 | J33: 补齐遗漏内容和适用场景，核对相关输入后组织复核，并保留复核结论。 | L33: 否
A34: 21 | B34: 22 | C34: 相关工作产品未完整覆盖本检查项要求的必要内容和适用场景，当前结果不能支撑该项要求已经全部落实。 | F34: 一般 | G34: 赵要浦 | H34: 2026-01-23 | I34: 2026-01-23 | J34: 补齐遗漏内容和适用场景，核对相关输入后组织复核，并保留复核结论。 | L34: 否

Sheet R016-审核配置管理过程-阶段
B1: 过程/产品审核报告
B2: 编号：ZDPX-03046/0.0-QA-审核报告-016
B3: 项目名称 | D3: 相控阵数字样机软件 | H3: 所处阶段 | J3: 需求分析阶段
B4: 审核对象（过程名称/产品名称） | F4: 审核配置管理过程-阶段
B5: 审核人 | D5: 高蕾 | F5: 审核日期 | H5: 2026-01-23
B6: 审核依据 | D6: ZDPX-03046/0.0-QA-检查单-016
B7: 本次审核依据《配 置 管 理 检 查 单》实施。经审核，发现2个不符合项。
B9: NC总数 | D9: 轻微 | F9: 一般 | H9: 严重
B10: =COUNTIF(B13:B14,"<>") | D10: =COUNTIF(F13:F14,"轻微") | F10: =COUNTIF(F13:F14,"一般") | H10: =COUNTIF(F13:F14,"严重")
B11: 不符合项问题（NC）列表
B12: 序号 | C12: 问题描述 | F12: 严重程度 | G12: 责任人 | H12: 提交日期 | I12: 计划关闭日期 | J12: 纠正措施
B13: 1 | C13: ='C016-审核配置管理过程-阶段'!C33 | F13: ='C016-审核配置管理过程-阶段'!F33 | G13: ='C016-审核配置管理过程-阶段'!G33 | H13: ='C016-审核配置管理过程-阶段'!H33 | I13: ='C016-审核配置管理过程-阶段'!I33 | J13: ='C016-审核配置管理过程-阶段'!J33
B14: 2 | C14: ='C016-审核配置管理过程-阶段'!C34 | F14: ='C016-审核配置管理过程-阶段'!F34 | G14: ='C016-审核配置管理过程-阶段'!G34 | H14: ='C016-审核配置管理过程-阶段'!H34 | I14: ='C016-审核配置管理过程-阶段'!I34 | J14: ='C016-审核配置管理过程-阶段'!J34
B16: 纠正措施验证情况：
B17: 已整改并验证通过；已整改并验证通过

Sheet C017-审核项目监控过程-阶段
A1: 项目监控检查单
A2: 编号：ZDPX-03046/0.0-QA-检查单-017
A3: 项目名称 | C3: 相控阵数字样机软件 | F3: 当前阶段 | H3: 需求分析阶段 | J3: 项目QA | L3: 高蕾
A4: 审核对象 | C4: 审核项目监控过程-阶段 | F4: 产品标识 | H4: — | J4: 产品版本 | L4: —
A6: 序号 | B6: 审核内容 | G6: 是 | H6: 否 | I6: 不适用 | J6: 严重程度 | L6: 备注
A7: 通用检查项
A8: 1 | B8: 本阶段的任务是否以任务分配表的形式分配到个人？ | G8: ✓
A9: 2 | B9: 项目组成员是否按时填写个人工作报告，记录个人完成任务的情况、工作量等信息？ | G9: ✓
A10: 3* | B10: 在每个跟踪节点，项目负责人是否对项目进度和工作量进行汇总，并与计划值进行比较？对于超过阈值的偏差是否进行了分析？ | G10: ✓
A11: 4 | B11: 每当工作产品完成时，项目负责人是否统计工作产品实际规模，并与计划值进行比较？对于超过阈值的偏差是否进行了分析？ | G11: ✓
A12: 5 | B12: 是否依据利益相关方参与计划，及时记录利益相关方参与情况？对出现的偏差有无进行分析？ | G12: ✓
A13: 6* | B13: 是否按体系要求对识别出的风险进行跟踪？ | G13: ✓
A14: 7* | B14: 当识别出新风险时，是否更新项目风险表并进行跟踪？ | G14: ✓
A15: 8 | B15: 是否对资源计划进行了跟踪？对出现的偏差有无进行分析？ | G15: ✓
A16: 9 | B16: 是否对培训计划进行了跟踪？对出现的偏差有无进行分析？ | G16: ✓
A17: 10 | B17: 项目负责人对项目跟踪过程中发现的问题是否及时记录，并制定纠正措施？ | G17: ✓
A18: 11 | B18: 纠正措施是否明确了责任人、验证人？ | G18: ✓
A19: 12* | B19: 当纠正措施会影响到对外承诺时，是否与利益相关方对纠正措施进行了评审？ | G19: ✓
A20: 13 | B20: 对已经识别出的项目问题是否进行了跟踪？ | H20: ✓ | J20: 一般 | K20: 必要内容覆盖不完整
A21: 14 | B21: 是否对纠正结果进行了验证？有无记录验证情况及验证时间？ | G21: ✓
A22: 15 | B22: 是否定期（双周、阶段末和里程碑）对采集的各项数据进行分析，形成测量分析报告？ | G22: ✓
A23: 16 | B23: 是否定期（双周、阶段末和里程碑）对质量工作进行总结，形成质量审核工作报告？ | G23: ✓
A24: 17 | B24: 是否定期（阶段末和里程碑）对配管工作进行总结，形成配置管理工作报告？ | G24: ✓
A25: 18 | B25: 是否定期（阶段末和里程碑）对需求管理工作进行总结，形成需求管理情况工作报告？ | G25: ✓
A26: 19* | B26: 项目负责人是否定期（双周、阶段末和里程碑）将工作进展及策划参数跟踪情况、问题及风险跟踪情况、偏差处理措施等进行汇总，形成项目进展报告？ | G26: ✓
A27: 20 | B27: 项目进展报告是否上报给项目总监，并通报给项目组人员？ | G27: ✓
A28: 21 | B28: 项目例会中是否对进展报告进行了交流，并对问题、风险、偏差等进行了讨论？ | G28: ✓
A29: 22 | B29: 项目例会有无形成会议纪要？ | H29: ✓ | J29: 一般 | K29: 必要内容覆盖不完整
A30: 23* | B30: 是否按计划实施里程碑评审？ | G30: ✓
A31: 24 | B31: 里程碑评审参会人员是否符合体系要求？ | G31: ✓
A32: 25* | B32: 里程碑评审会的材料是否准备齐全？ | G32: ✓
A33: 26 | B33: 里程碑评审是否对评审节点前的项目进展情况、规模、进度、工作量、问题和风险等的跟踪情况进行了分析并标识出偏差。 | G33: ✓
A34: 27 | B34: 对于超出阈值的偏差是否分析了原因，并提出相应的措施 | G34: ✓
A35: 28 | B35: 是否对新识别的问题制定了纠正措施 | G35: ✓
A36: 29* | B36: 里程碑评审后是否形成评审报告，并指定负责人处理评审意见。 | G36: ✓
A37: 30 | B37: 对评审意见的处理有无进行跟踪，直到形成闭环 | G37: ✓
A38: 31 | B38: 需对软件开发计划进行变更时，是否按要求办理了变更审批手续 | G38: ✓
A39: 32 | B39: 是否按规程修订项目软件开发计划及相关文档 | G39: ✓
A40: 33* | B40: 对外部承诺的变更是否经公司CCB的批准 | G40: ✓
A41: 34 | B41: 是否有通知受影响的组和个人的记录 | G41: ✓
...

Sheet R017-审核项目监控过程-阶段
B1: 过程/产品审核报告
B2: 编号：ZDPX-03046/0.0-QA-审核报告-017
B3: 项目名称 | D3: 相控阵数字样机软件 | H3: 所处阶段 | J3: 需求分析阶段
B4: 审核对象（过程名称/产品名称） | F4: 审核项目监控过程-阶段
B5: 审核人 | D5: 高蕾 | F5: 审核日期 | H5: 2026-01-23
B6: 审核依据 | D6: ZDPX-03046/0.0-QA-检查单-017
B7: 本次审核依据《项目监控检查单》实施。经审核，发现2个不符合项。
B9: NC总数 | D9: 轻微 | F9: 一般 | H9: 严重
B10: =COUNTIF(B13:B14,"<>") | D10: =COUNTIF(F13:F14,"轻微") | F10: =COUNTIF(F13:F14,"一般") | H10: =COUNTIF(F13:F14,"严重")
B11: 不符合项问题（NC）列表
B12: 序号 | C12: 问题描述 | F12: 严重程度 | G12: 责任人 | H12: 提交日期 | I12: 计划关闭日期 | J12: 纠正措施
B13: 1 | C13: ='C017-审核项目监控过程-阶段'!C45 | F13: ='C017-审核项目监控过程-阶段'!F45 | G13: ='C017-审核项目监控过程-阶段'!G45 | H13: ='C017-审核项目监控过程-阶段'!H45 | I13: ='C017-审核项目监控过程-阶段'!I45 | J13: ='C017-审核项目监控过程-阶段'!J45
B14: 2 | C14: ='C017-审核项目监控过程-阶段'!C46 | F14: ='C017-审核项目监控过程-阶段'!F46 | G14: ='C017-审核项目监控过程-阶段'!G46 | H14: ='C017-审核项目监控过程-阶段'!H46 | I14: ='C017-审核项目监控过程-阶段'!I46 | J14: ='C017-审核项目监控过程-阶段'!J46
B16: 纠正措施验证情况：
B17: 已整改并验证通过；已整改并验证通过

Sheet C018-审核测量与绩效管理过程-阶段
A1: 测量与绩效管理检查单
A2: 编号：ZDPX-03046/0.0-QA-检查单-018
A3: 项目名称 | C3: 相控阵数字样机软件 | F3: 当前阶段 | H3: 需求分析阶段 | J3: 项目QA | L3: 高蕾
A4: 审核对象 | C4: 审核测量与绩效管理过程-阶段 | F4: 产品标识 | H4: — | J4: 产品版本 | L4: —
A6: 序号 | B6: 审核内容 | G6: 是 | H6: 否 | I6: 不适用 | J6: 严重程度 | L6: 备注
A7: 通用检查项
A8: 1* | B8: 是否建立了项目的测量目标？ | G8: ✓
A9: 2 | B9: 是否根据测量目标确定了项目所要使用的测量项？ | G9: ✓
A10: 3 | B10: 是否指定了测量分析的负责人？ | G10: ✓
A11: 4 | B11: 是否确定了测量数据的存储方式？ | G11: ✓
A12: 5 | B12: 是否明确了项目测量项的采集时机、采集方法、采集位置及采集人？ | G12: ✓
A13: 6 | B13: 是否指明了对测量数据的分析方法、表达方式等？ | G13: ✓
A14: 7 | B14: 是否明确了测量数据分析结果的交流时机、交流方式？ | G14: ✓
A15: 8 | B15: 是否制定了项目的测量与分析计划？并对测量分析计划进行了评审？ | H15: ✓ | J15: 一般 | K15: 必要内容覆盖不完整
A16: 9 | B16: 当项目有新增测量项时，是否经过软件工程过程组的审批？ | G16: ✓
A17: 10 | B17: 是否按照测量与分析计划，在规定的时间和采集点收集测量数据？ | G17: ✓
A18: 11 | B18: 是否将采集到的数据（需要时进行预处理）存入指定的数据分析工具平台？ | G18: ✓
A19: 12 | B19: 是否在计划时间点对采集到的测量数据进行分析？ | G19: ✓
A20: 13 | B20: 是否将分析结果汇总形成测量与分析报告？ | G20: ✓
A21: 14 | B21: 是否与项目组、利益相关方（必要时）交流了测量数据的分析结果？ | G21: ✓
A22: 15 | B22: 项目实施过程中，测量相关的数据和文档有无得到有效控制？ | G22: ✓
A24: 不符合项问题明细
A25: 问题ID | B25: 检查项 | C25: 问题描述 | F25: 严重程度 | G25: 责任人 | H25: 提交日期 | I25: 计划关闭日期 | J25: 纠正措施 | L25: 关闭
A26: 24 | B26: 8 | C26: 相关工作产品未完整覆盖本检查项要求的必要内容和适用场景，当前结果不能支撑该项要求已经全部落实。 | F26: 一般 | G26: 赵要浦 | H26: 2026-01-23 | I26: 2026-01-23 | J26: 补齐遗漏内容和适用场景，核对相关输入后组织复核，并保留复核结论。 | L26: 否

Sheet R018-审核测量与绩效管理过程-阶段
B1: 过程/产品审核报告
B2: 编号：ZDPX-03046/0.0-QA-审核报告-018
B3: 项目名称 | D3: 相控阵数字样机软件 | H3: 所处阶段 | J3: 需求分析阶段
B4: 审核对象（过程名称/产品名称） | F4: 审核测量与绩效管理过程-阶段
B5: 审核人 | D5: 高蕾 | F5: 审核日期 | H5: 2026-01-23
B6: 审核依据 | D6: ZDPX-03046/0.0-QA-检查单-018
B7: 本次审核依据《测量与绩效管理检查单》实施。经审核，发现1个不符合项。
B9: NC总数 | D9: 轻微 | F9: 一般 | H9: 严重
B10: =COUNTIF(B13:B13,"<>") | D10: =COUNTIF(F13:F13,"轻微") | F10: =COUNTIF(F13:F13,"一般") | H10: =COUNTIF(F13:F13,"严重")
B11: 不符合项问题（NC）列表
B12: 序号 | C12: 问题描述 | F12: 严重程度 | G12: 责任人 | H12: 提交日期 | I12: 计划关闭日期 | J12: 纠正措施
B13: 1 | C13: ='C018-审核测量与绩效管理过程-阶段'!C26 | F13: ='C018-审核测量与绩效管理过程-阶段'!F26 | G13: ='C018-审核测量与绩效管理过程-阶段'!G26 | H13: ='C018-审核测量与绩效管理过程-阶段'!H26 | I13: ='C018-审核测量与绩效管理过程-阶段'!I26 | J13: ='C018-审核测量与绩效管理过程-阶段'!J26
B15: 纠正措施验证情况：
B16: 已整改并验证通过

Sheet _计算
A1: 流水号 | B1: 审核对象 | C1: 问题序号 | D1: NC类型 | E1: 问题描述 | F1: 严重程度 | G1: 是否关闭 | H1: 归组日期 | I1: 节点类型 | J1: 审核日期
A2: 6 | B2: ='R006-相控阵数字样机软件测量分析计划'!F4 | C2: ='R006-相控阵数字样机软件测量分析计划'!B13 | D2: 工作产品 | E2: ='R006-相控阵数字样机软件测量分析计划'!C13 | F2: ='R006-相控阵数字样机软件测量分析计划'!F13 | G2: 否 | H2: 2026-01-12 | I2: 双周 | J2: 2026-01-06
A3: 6 | B3: ='R006-相控阵数字样机软件测量分析计划'!F4 | C3: ='R006-相控阵数字样机软件测量分析计划'!B14 | D3: 工作产品 | E3: ='R006-相控阵数字样机软件测量分析计划'!C14 | F3: ='R006-相控阵数字样机软件测量分析计划'!F14 | G3: 否 | H3: 2026-01-12 | I3: 双周 | J3: 2026-01-06
A4: 7 | B4: ='R007-相控阵数字样机软件质量保证计划'!F4 | C4: ='R007-相控阵数字样机软件质量保证计划'!B13 | D4: 工作产品 | E4: ='R007-相控阵数字样机软件质量保证计划'!C13 | F4: ='R007-相控阵数字样机软件质量保证计划'!F13 | G4: 否 | H4: 2026-01-12 | I4: 双周 | J4: 2026-01-06
A5: 7 | B5: ='R007-相控阵数字样机软件质量保证计划'!F4 | C5: ='R007-相控阵数字样机软件质量保证计划'!B14 | D5: 工作产品 | E5: ='R007-相控阵数字样机软件质量保证计划'!C14 | F5: ='R007-相控阵数字样机软件质量保证计划'!F14 | G5: 否 | H5: 2026-01-12 | I5: 双周 | J5: 2026-01-06
A6: 10 | B6: ='R010-审核项目监控过程-双周'!F4 | C6: ='R010-审核项目监控过程-双周'!B13 | D6: PMC | E6: ='R010-审核项目监控过程-双周'!C13 | F6: ='R010-审核项目监控过程-双周'!F13 | G6: 否 | H6: 2026-01-12 | I6: 双周 | J6: 2026-01-12
A7: 11 | B7: ='R011-审核测量与绩效管理过程-双周'!F4 | C7: ='R011-审核测量与绩效管理过程-双周'!B13 | D7: MPM | E7: ='R011-审核测量与绩效管理过程-双周'!C13 | F7: ='R011-审核测量与绩效管理过程-双周'!F13 | G7: 否 | H7: 2026-01-12 | I7: 双周 | J7: 2026-01-12
A8: 11 | B8: ='R011-审核测量与绩效管理过程-双周'!F4 | C8: ='R011-审核测量与绩效管理过程-双周'!B14 | D8: MPM | E8: ='R011-审核测量与绩效管理过程-双周'!C14 | F8: ='R011-审核测量与绩效管理过程-双周'!F14 | G8: 否 | H8: 2026-01-12 | I8: 双周 | J8: 2026-01-12
A9: 12 | B9: ='R012-相控阵数字样机软件需求规格说明'!F4 | C9: ='R012-相控阵数字样机软件需求规格说明'!B13 | D9: 工作产品 | E9: ='R012-相控阵数字样机软件需求规格说明'!C13 | F9: ='R012-相控阵数字样机软件需求规格说明'!F13 | G9: 否 | H9: 2026-01-23 | I9: 阶段 | J9: 2026-01-15
A10: 12 | B10: ='R012-相控阵数字样机软件需求规格说明'!F4 | C10: ='R012-相控阵数字样机软件需求规格说明'!B14 | D10: 工作产品 | E10: ='R012-相控阵数字样机软件需求规格说明'!C14 | F10: ='R012-相控阵数字样机软件需求规格说明'!F14 | G10: 否 | H10: 2026-01-23 | I10: 阶段 | J10: 2026-01-15
A11: 13 | B11: ='R013-相控阵数字样机软件测试计划'!F4 | C11: ='R013-相控阵数字样机软件测试计划'!B13 | D11: 工作产品 | E11: ='R013-相控阵数字样机软件测试计划'!C13 | F11: ='R013-相控阵数字样机软件测试计划'!F13 | G11: 否 | H11: 2026-01-23 | I11: 阶段 | J11: 2026-01-21
A12: 13 | B12: ='R013-相控阵数字样机软件测试计划'!F4 | C12: ='R013-相控阵数字样机软件测试计划'!B14 | D12: 工作产品 | E12: ='R013-相控阵数字样机软件测试计划'!C14 | F12: ='R013-相控阵数字样机软件测试计划'!F14 | G12: 否 | H12: 2026-01-23 | I12: 阶段 | J12: 2026-01-21
A13: 14 | B13: ='R014-审核验证与确认过程'!F4 | C13: ='R014-审核验证与确认过程'!B13 | D13: VV | E13: ='R014-审核验证与确认过程'!C13 | F13: ='R014-审核验证与确认过程'!F13 | G13: 否 | H13: 2026-01-23 | I13: 阶段 | J13: 2026-01-23
A14: 14 | B14: ='R014-审核验证与确认过程'!F4 | C14: ='R014-审核验证与确认过程'!B14 | D14: VV | E14: ='R014-审核验证与确认过程'!C14 | F14: ='R014-审核验证与确认过程'!F14 | G14: 否 | H14: 2026-01-23 | I14: 阶段 | J14: 2026-01-23
A15: 15 | B15: ='R015-审核需求开发与管理过程'!F4 | C15: ='R015-审核需求开发与管理过程'!B13 | D15: RDM | E15: ='R015-审核需求开发与管理过程'!C13 | F15: ='R015-审核需求开发与管理过程'!F13 | G15: 否 | H15: 2026-01-23 | I15: 阶段 | J15: 2026-01-23
A16: 15 | B16: ='R015-审核需求开发与管理过程'!F4 | C16: ='R015-审核需求开发与管理过程'!B14 | D16: RDM | E16: ='R015-审核需求开发与管理过程'!C14 | F16: ='R015-审核需求开发与管理过程'!F14 | G16: 否 | H16: 2026-01-23 | I16: 阶段 | J16: 2026-01-23
A17: 16 | B17: ='R016-审核配置管理过程-阶段'!F4 | C17: ='R016-审核配置管理过程-阶段'!B13 | D17: CM | E17: ='R016-审核配置管理过程-阶段'!C13 | F17: ='R016-审核配置管理过程-阶段'!F13 | G17: 否 | H17: 2026-01-23 | I17: 阶段 | J17: 2026-01-23
A18: 16 | B18: ='R016-审核配置管理过程-阶段'!F4 | C18: ='R016-审核配置管理过程-阶段'!B14 | D18: CM | E18: ='R016-审核配置管理过程-阶段'!C14 | F18: ='R016-审核配置管理过程-阶段'!F14 | G18: 否 | H18: 2026-01-23 | I18: 阶段 | J18: 2026-01-23
A19: 17 | B19: ='R017-审核项目监控过程-阶段'!F4 | C19: ='R017-审核项目监控过程-阶段'!B13 | D19: PMC | E19: ='R017-审核项目监控过程-阶段'!C13 | F19: ='R017-审核项目监控过程-阶段'!F13 | G19: 否 | H19: 2026-01-23 | I19: 阶段 | J19: 2026-01-23
A20: 17 | B20: ='R017-审核项目监控过程-阶段'!F4 | C20: ='R017-审核项目监控过程-阶段'!B14 | D20: PMC | E20: ='R017-审核项目监控过程-阶段'!C14 | F20: ='R017-审核项目监控过程-阶段'!F14 | G20: 否 | H20: 2026-01-23 | I20: 阶段 | J20: 2026-01-23
A21: 18 | B21: ='R018-审核测量与绩效管理过程-阶段'!F4 | C21: ='R018-审核测量与绩效管理过程-阶段'!B13 | D21: MPM | E21: ='R018-审核测量与绩效管理过程-阶段'!C13 | F21: ='R018-审核测量与绩效管理过程-阶段'!F13 | G21: 否 | H21: 2026-01-23 | I21: 阶段 | J21: 2026-01-23
