Workbook

Sheet 审核目录
A1: 阶段质量审核记录目录
A2: 项目：相控阵数字样机软件 | C2: 阶段：软件编码与单元测试阶段
A4: 流水号 | B4: 审核对象 | C4: 检查单 | D4: 审核报告
A5: 28 | B5: 审核项目策划过程 | C5: 打开检查单 | D5: 打开审核报告
A6: 29 | B6: 审核项目监控-双周 | C6: 打开检查单 | D6: 打开审核报告
A7: 30 | B7: 审核测量与绩效管理-双周 | C7: 打开检查单 | D7: 打开审核报告
A8: 31 | B8: 审核配置管理过程-月 | C8: 打开检查单 | D8: 打开审核报告
A9: 32 | B9: 审核验证与确认过程 | C9: 打开检查单 | D9: 打开审核报告
A10: 33 | B10: 审核需求开发与管理过程 | C10: 打开检查单 | D10: 打开审核报告
A11: 34 | B11: 审核配置管理过程-阶段末 | C11: 打开检查单 | D11: 打开审核报告
A12: 35 | B12: 审核项目监控-阶段 | C12: 打开检查单 | D12: 打开审核报告
A13: 36 | B13: 审核测量与绩效管理-阶段 | C13: 打开检查单 | D13: 打开审核报告
A14: 38 | B14: 相控阵数字样机软件单元测试报告 | C14: 打开检查单 | D14: 打开审核报告

Sheet 阶段质量审核工作报告
A1: 质量审核工作报告
A2: 编号：ZDPX-03046/0.0-QA-质量报告-004
A3: 项目名称 | C3: 相控阵数字样机软件 | G3: 报告阶段 | I3: 软件编码与单元测试阶段
A4: 报告起止日期 | C4: 2026-02-10 至 2026-03-11 | G4: 项目QA | I4: 高蕾
A6: 审核情况汇总
A7: 流水号 | B7: 审核对象 | C7: 审核日期 | D7: 节点 | E7: NC类型 | F7: 问题描述 | J7: 严重程度 | K7: 是否关闭 | L7: 审核状态
A8: 双周汇总：2026-02-24
A9: 28 | B9: 审核项目策划过程 | C9: 2026-02-11 | D9: 双周 | F9: 未发现不符合项 | L9: 未确认
A10: 29 | B10: 审核项目监控-双周 | C10: 2026-02-24 | D10: 双周 | F10: 未发现不符合项 | L10: 未确认
A11: 30 | B11: 审核测量与绩效管理-双周 | C11: 2026-02-24 | D11: 双周 | F11: 未发现不符合项 | L11: 未确认
A12: 节点统计 | E12: NC总数 | F12: =COUNTIF(J9:J11,"?*") | G12: 未关闭 | H12: =COUNTIF(K9:K11,"否") | I12: 严重 | J12: =COUNTIF(J9:J11,"严重")
A14: 阶段汇总：2026-03-11
A15: 31 | B15: 审核配置管理过程-月 | C15: 2026-02-27 | D15: 阶段 | F15: 未发现不符合项 | L15: 未确认
A16: 32 | B16: ='_计算'!B2 | C16: 2026-03-11 | D16: 阶段 | E16: ='_计算'!D2 | F16: ='_计算'!E2 | J16: ='_计算'!F2 | K16: ='_计算'!G2 | L16: 未确认
A17: 33 | B17: ='_计算'!B3 | C17: 2026-03-11 | D17: 阶段 | E17: ='_计算'!D3 | F17: ='_计算'!E3 | J17: ='_计算'!F3 | K17: ='_计算'!G3 | L17: 未确认
A18: 34 | B18: 审核配置管理过程-阶段末 | C18: 2026-03-11 | D18: 阶段 | F18: 未发现不符合项 | L18: 未确认
A19: 35 | B19: ='_计算'!B4 | C19: 2026-03-11 | D19: 阶段 | E19: ='_计算'!D4 | F19: ='_计算'!E4 | J19: ='_计算'!F4 | K19: ='_计算'!G4 | L19: 未确认
A20: 35 | B20: ='_计算'!B5 | C20: 2026-03-11 | D20: 阶段 | E20: ='_计算'!D5 | F20: ='_计算'!E5 | J20: ='_计算'!F5 | K20: ='_计算'!G5 | L20: 未确认
A21: 36 | B21: ='_计算'!B6 | C21: 2026-03-11 | D21: 阶段 | E21: ='_计算'!D6 | F21: ='_计算'!E6 | J21: ='_计算'!F6 | K21: ='_计算'!G6 | L21: 未确认
A22: 36 | B22: ='_计算'!B7 | C22: 2026-03-11 | D22: 阶段 | E22: ='_计算'!D7 | F22: ='_计算'!E7 | J22: ='_计算'!F7 | K22: ='_计算'!G7 | L22: 未确认
A23: 38 | B23: ='_计算'!B8 | C23: 2026-03-11 | D23: 阶段 | E23: ='_计算'!D8 | F23: ='_计算'!E8 | J23: ='_计算'!F8 | K23: ='_计算'!G8 | L23: 未确认
A24: 节点统计 | E24: NC总数 | F24: =COUNTIF(J15:J23,"?*") | G24: 未关闭 | H24: =COUNTIF(K15:K23,"否") | I24: 严重 | J24: =COUNTIF(J15:J23,"严重")
A26: 阶段汇总统计
A27: 产品NC总数 | B27: =COUNTIF('_计算'!D2:D8,"工作产品") | C27: 过程NC总数 | D27: =COUNTIFS('_计算'!D2:D8,"<>工作产品",'_计算'!D2:D8,"<>") | E27: 未关闭NC数 | F27: =COUNTIF('_计算'!G2:G8,"否") | G27: 轻微 | H27: =COUNTIF('_计算'!F2:F8,"轻微") | I27: 一般 | J27: =COUNTIF('_计算'!F2:F8,"一般") | K27: 严重 | L27: =COUNTIF('_计算'!F2:F8,"严重")
A28: RDM | B28: PP | C28: PMC | D28: CM | E28: MT | F28: MPM | G28: VV | H28: LD | I28: II | J28: 工作产品 | K28: 总计
A29: =COUNTIF('_计算'!D2:D8,"RDM") | B29: =COUNTIF('_计算'!D2:D8,"PP") | C29: =COUNTIF('_计算'!D2:D8,"PMC") | D29: =COUNTIF('_计算'!D2:D8,"CM") | E29: =COUNTIF('_计算'!D2:D8,"MT") | F29: =COUNTIF('_计算'!D2:D8,"MPM") | G29: =COUNTIF('_计算'!D2:D8,"VV") | H29: =COUNTIF('_计算'!D2:D8,"LD") | I29: =COUNTIF('_计算'!D2:D8,"II") | J29: =COUNTIF('_计算'!D2:D8,"工作产品") | K29: =SUM(A29:J29)

Sheet C028-审核项目策划过程
A1: 项目策划检查单
A2: 编号：ZDPX-03046/0.0-QA-检查单-028
A3: 项目名称 | C3: 相控阵数字样机软件 | F3: 当前阶段 | H3: 软件编码与单元测试阶段 | J3: 项目QA | L3: 高蕾
A4: 审核对象 | C4: 审核项目策划过程 | F4: 产品标识 | H4: — | J4: 产品版本 | L4: —
A6: 序号 | B6: 审核内容 | G6: 是 | H6: 否 | I6: 不适用 | J6: 严重程度 | L6: 备注
A7: 通用检查项
A8: 1 | B8: 是否对软件产品进行了标识并记录？ | G8: ✓
A9: 2* | B9: 是否为软件项目选择了生存周期模型，并说明了理由？ | G9: ✓
A10: 3* | B10: 是否对标准过程进行了裁剪，确定了软件项目的过程？ | G10: ✓
A11: 4 | B11: 是否生成工作分解结构并记录？ | G11: ✓
A12: 5 | B12: 是否进行了软件工作产品规模估计？ | G12: ✓
A13: 6 | B13: 是否进行了工作量/成本估计？ | G13: ✓
A14: 7 | B14: 所采用的估计方法是否按正确步骤实施？ | G14: ✓
A15: 8 | B15: 估算结果是否形成了估算报告？ | G15: ✓
A16: 9 | B16: 是否记录了估计的假设数据及假设的依据？ | G16: ✓
A17: 10 | B17: 是否明确并记录了关键路径、任务参与方、利益相关方、资源需求等进度安排依据？ | G17: ✓
A18: 11* | B18: 是否依据估算结果进行了进度安排？ | G18: ✓
A19: 12* | B19: 是否定义了软件项目的里程碑？ | G19: ✓
... A33: 26 | B33: 阶段详细策划的结果是否通知到相关项目组成员，以获得对阶段详细计划的承诺？ | G33: ✓
A35: 不符合项问题明细
A36: 问题ID | B36: 检查项 | C36: 问题描述 | F36: 严重程度 | G36: 责任人 | H36: 提交日期 | I36: 计划关闭日期 | J36: 纠正措施 | L36: 关闭
A37: 本次审核未发现不符合项。

Sheet R028-审核项目策划过程
B1: 过程/产品审核报告
B2: 编号：ZDPX-03046/0.0-QA-审核报告-028
B3: 项目名称 | D3: 相控阵数字样机软件 | H3: 所处阶段 | J3: 软件编码与单元测试阶段
B4: 审核对象（过程名称/产品名称） | F4: 审核项目策划过程
B5: 审核人 | D5: 高蕾 | F5: 审核日期 | H5: 2026-02-11
B6: 审核依据 | D6: ZDPX-03046/0.0-QA-检查单-028
B7: 本次审核依据《项目策划检查单》实施。经审核，未发现不符合项。
B9: NC总数 | D9: 轻微 | F9: 一般 | H9: 严重
B10: =0 | D10: =0 | F10: =0 | H10: =0
B11: 不符合项问题（NC）列表
B12: 序号 | C12: 问题描述 | F12: 严重程度 | G12: 责任人 | H12: 提交日期 | I12: 计划关闭日期 | J12: 纠正措施
B13: 本次审核未发现不符合项。
B15: 纠正措施验证情况：
B16: 不适用

Sheet C029-审核项目监控-双周
A1: 项目监控检查单
A2: 编号：ZDPX-03046/0.0-QA-检查单-029
A3: 项目名称 | C3: 相控阵数字样机软件 | F3: 当前阶段 | H3: 软件编码与单元测试阶段 | J3: 项目QA | L3: 高蕾
A4: 审核对象 | C4: 审核项目监控-双周 | F4: 产品标识 | H4: — | J4: 产品版本 | L4: —
A6: 序号 | B6: 审核内容 | G6: 是 | H6: 否 | I6: 不适用 | J6: 严重程度 | L6: 备注
A7: 通用检查项
A8: 1 | B8: 本阶段的任务是否以任务分配表的形式分配到个人？ | G8: ✓
A9: 2 | B9: 项目组成员是否按时填写个人工作报告，记录个人完成任务的情况、工作量等信息？ | G9: ✓
A10: 3* | B10: 在每个跟踪节点，项目负责人是否对项目进度和工作量进行汇总，并与计划值进行比较？对于超过阈值的偏差是否进行了分析？ | G10: ✓
A11: 4 | B11: 每当工作产品完成时，项目负责人是否统计工作产品实际规模，并与计划值进行比较？对于超过阈值的偏差是否进行了分析？ | G11: ✓
A12: 5 | B12: 是否依据利益相关方参与计划，及时记录利益相关方参与情况？对出现的偏差有无进行分析？ | G12: ✓
A13: 6* | B13: 是否按体系要求对识别出的风险进行跟踪？ | G13: ✓
A14: 7* | B14: 当识别出新风险时，是否更新项目风险表并进行跟踪？ | G14: ✓
A15: 8 | B15: 是否对资源计划进行了跟踪？对出现的偏差有无进行分析？ | G15: ✓
A16: 9 | B16: 是否对培训计划进行了跟踪？对出现的偏差有无进行分析？ | G16: ✓
A17: 10 | B17: 项目负责人对项目跟踪过程中发现的问题是否及时记录，并制定纠正措施？ | G17: ✓
A18: 11 | B18: 纠正措施是否明确了责任人、验证人？ | G18: ✓
A19: 12* | B19: 当纠正措施会影响到对外承诺时，是否与利益相关方对纠正措施进行了评审？ | G19: ✓
... A41: 34 | B41: 是否有通知受影响的组和个人的记录 | G41: ✓
A43: 不符合项问题明细
A44: 问题ID | B44: 检查项 | C44: 问题描述 | F44: 严重程度 | G44: 责任人 | H44: 提交日期 | I44: 计划关闭日期 | J44: 纠正措施 | L44: 关闭
A45: 本次审核未发现不符合项。

Sheet R029-审核项目监控-双周
B1: 过程/产品审核报告
B2: 编号：ZDPX-03046/0.0-QA-审核报告-029
B3: 项目名称 | D3: 相控阵数字样机软件 | H3: 所处阶段 | J3: 软件编码与单元测试阶段
B4: 审核对象（过程名称/产品名称） | F4: 审核项目监控-双周
B5: 审核人 | D5: 高蕾 | F5: 审核日期 | H5: 2026-02-24
B6: 审核依据 | D6: ZDPX-03046/0.0-QA-检查单-029
B7: 本次审核依据《项目监控检查单》实施。经审核，未发现不符合项。
B9: NC总数 | D9: 轻微 | F9: 一般 | H9: 严重
B10: =0 | D10: =0 | F10: =0 | H10: =0
B11: 不符合项问题（NC）列表
B12: 序号 | C12: 问题描述 | F12: 严重程度 | G12: 责任人 | H12: 提交日期 | I12: 计划关闭日期 | J12: 纠正措施
B13: 本次审核未发现不符合项。
B15: 纠正措施验证情况：
B16: 不适用

Sheet C030-审核测量与绩效管理-双周
A1: 测量与绩效管理检查单
A2: 编号：ZDPX-03046/0.0-QA-检查单-030
A3: 项目名称 | C3: 相控阵数字样机软件 | F3: 当前阶段 | H3: 软件编码与单元测试阶段 | J3: 项目QA | L3: 高蕾
A4: 审核对象 | C4: 审核测量与绩效管理-双周 | F4: 产品标识 | H4: — | J4: 产品版本 | L4: —
A6: 序号 | B6: 审核内容 | G6: 是 | H6: 否 | I6: 不适用 | J6: 严重程度 | L6: 备注
A7: 通用检查项
A8: 1* | B8: 是否建立了项目的测量目标？ | G8: ✓
A9: 2 | B9: 是否根据测量目标确定了项目所要使用的测量项？ | G9: ✓
A10: 3 | B10: 是否指定了测量分析的负责人？ | G10: ✓
A11: 4 | B11: 是否确定了测量数据的存储方式？ | G11: ✓
A12: 5 | B12: 是否明确了项目测量项的采集时机、采集方法、采集位置及采集人？ | G12: ✓
A13: 6 | B13: 是否指明了对测量数据的分析方法、表达方式等？ | G13: ✓
A14: 7 | B14: 是否明确了测量数据分析结果的交流时机、交流方式？ | G14: ✓
A15: 8 | B15: 是否制定了项目的测量与分析计划？并对测量分析计划进行了评审？ | G15: ✓
A16: 9 | B16: 当项目有新增测量项时，是否经过软件工程过程组的审批？ | G16: ✓
A17: 10 | B17: 是否按照测量与分析计划，在规定的时间和采集点收集测量数据？ | G17: ✓
A18: 11 | B18: 是否将采集到的数据（需要时进行预处理）存入指定的数据分析工具平台？ | G18: ✓
A19: 12 | B19: 是否在计划时间点对采集到的测量数据进行分析？ | G19: ✓
... A22: 15 | B22: 项目实施过程中，测量相关的数据和文档有无得到有效控制？ | G22: ✓
A24: 不符合项问题明细
A25: 问题ID | B25: 检查项 | C25: 问题描述 | F25: 严重程度 | G25: 责任人 | H25: 提交日期 | I25: 计划关闭日期 | J25: 纠正措施 | L25: 关闭
A26: 本次审核未发现不符合项。

Sheet R030-审核测量与绩效管理-双周
B1: 过程/产品审核报告
B2: 编号：ZDPX-03046/0.0-QA-审核报告-030
B3: 项目名称 | D3: 相控阵数字样机软件 | H3: 所处阶段 | J3: 软件编码与单元测试阶段
B4: 审核对象（过程名称/产品名称） | F4: 审核测量与绩效管理-双周
B5: 审核人 | D5: 高蕾 | F5: 审核日期 | H5: 2026-02-24
B6: 审核依据 | D6: ZDPX-03046/0.0-QA-检查单-030
B7: 本次审核依据《测量与绩效管理检查单》实施。经审核，未发现不符合项。
B9: NC总数 | D9: 轻微 | F9: 一般 | H9: 严重
B10: =0 | D10: =0 | F10: =0 | H10: =0
B11: 不符合项问题（NC）列表
B12: 序号 | C12: 问题描述 | F12: 严重程度 | G12: 责任人 | H12: 提交日期 | I12: 计划关闭日期 | J12: 纠正措施
B13: 本次审核未发现不符合项。
B15: 纠正措施验证情况：
B16: 不适用

Sheet C031-审核配置管理过程-月
A1: 配 置 管 理 检 查 单
A2: 编号：ZDPX-03046/0.0-QA-检查单-031
A3: 项目名称 | C3: 相控阵数字样机软件 | F3: 当前阶段 | H3: 软件编码与单元测试阶段 | J3: 项目QA | L3: 高蕾
A4: 审核对象 | C4: 审核配置管理过程-月 | F4: 产品标识 | H4: — | J4: 产品版本 | L4: —
A6: 序号 | B6: 审核内容 | G6: 是 | H6: 否 | I6: 不适用 | J6: 严重程度 | L6: 备注
A7: 通用检查项
A8: 1 | B8: 是否为项目建立了受控库和开发库？ | G8: ✓
A9: 2* | B9: 是否按计划对配置项进行了受控管理？ | G9: ✓
A10: 3 | B10: 配置项的出入库单填写是否正确？ | G10: ✓
A11: 4 | B11: 受控库中配置项和基线的标识是否遵循了标识规则？ | G11: ✓
A12: 5* | B12: 受控库中基线的组成配置项是否与配置管理计划一致？ | G12: ✓
A13: 6 | B13: 受控库中每个基线版本是否都对应基线发布单？ | G13: ✓
A14: 7 | B14: 基线的建立和和变更情况是否通报给所有受影响的组和个人？ | G14: ✓
A15: 8 | B15: 配置项出入库、基线发布是否都经过了正确的审批？ | G15: ✓
A16: 9 | B16: 受控库是否按配置管理计划中的备份策略进行了备份？ | G16: ✓
A17: 10 | B17: 开发库的使用与配置管理计划要求是否一致？ | G17: ✓
A18: 11 | B18: 环境配置项有无受控管理？ | G18: ✓
A19: 12* | B19: 提交变更申请时，是否具体描述了需变更的内容，并进行了影响域分析？ | G19: ✓
... A29: 22 | B29: 配置管理报告内容是否完整 | G29: ✓
A31: 不符合项问题明细
A32: 问题ID | B32: 检查项 | C32: 问题描述 | F32: 严重程度 | G32: 责任人 | H32: 提交日期 | I32: 计划关闭日期 | J32: 纠正措施 | L32: 关闭
A33: 本次审核未发现不符合项。

Sheet R031-审核配置管理过程-月
B1: 过程/产品审核报告
B2: 编号：ZDPX-03046/0.0-QA-审核报告-031
B3: 项目名称 | D3: 相控阵数字样机软件 | H3: 所处阶段 | J3: 软件编码与单元测试阶段
B4: 审核对象（过程名称/产品名称） | F4: 审核配置管理过程-月
B5: 审核人 | D5: 高蕾 | F5: 审核日期 | H5: 2026-02-27
B6: 审核依据 | D6: ZDPX-03046/0.0-QA-检查单-031
B7: 本次审核依据《配 置 管 理 检 查 单》实施。经审核，未发现不符合项。
B9: NC总数 | D9: 轻微 | F9: 一般 | H9: 严重
B10: =0 | D10: =0 | F10: =0 | H10: =0
B11: 不符合项问题（NC）列表
B12: 序号 | C12: 问题描述 | F12: 严重程度 | G12: 责任人 | H12: 提交日期 | I12: 计划关闭日期 | J12: 纠正措施
B13: 本次审核未发现不符合项。
B15: 纠正措施验证情况：
B16: 不适用

Sheet C032-审核验证与确认过程
A1: 验证与确认检查单
A2: 编号：ZDPX-03046/0.0-QA-检查单-032
A3: 项目名称 | C3: 相控阵数字样机软件 | F3: 当前阶段 | H3: 软件编码与单元测试阶段 | J3: 项目QA | L3: 高蕾
A4: 审核对象 | C4: 审核验证与确认过程 | F4: 产品标识 | H4: — | J4: 产品版本 | L4: —
A6: 序号 | B6: 审核内容 | G6: 是 | H6: 否 | I6: 不适用 | J6: 严重程度 | L6: 备注
A7: 通用检查项
A8: 1* | B8: 有无按计划对本阶段工作产品实施验证与确认活动？ | G8: ✓
A9: 工作产品评审过程
A10: 1 | B10: 项目策划时有无制定评审计划，对评审形式、评审对象和评审时机进行明确？ | G10: ✓
A11: 2 | B11: 提交评审的文档是否经过项目QA的产品审核？ | G11: ✓
A12: 3 | B12: 评审前是否基于检查单模板准备了评审检查单？ | G12: ✓
A13: 4 | B13: 若评审检查单的检查项有修改时，是否经过EPG组的审批？ | G13: ✓
A14: 5 | B14: 参加评审的人员是否符合要求(依据相关过程文件规定) | H14: ✓ | J14: 一般 | K14: 必要内容覆盖不完整
A15: 6 | B15: 评审是否采取了正确的形式？（会议或审签） | G15: ✓
A16: 7* | B16: 是否记录了评审中发现的缺陷，并按要求形成了评审报告？ | G16: ✓
A17: 8 | B17: 对于评审中发现的缺陷，是否指定了负责修改人？ | G17: ✓
A18: 9 | B18: 是否指定了负责人对评审缺陷的处理情况进行跟踪和验证？是否有跟踪验证的记录？ | G18: ✓
A19: 10* | B19: 评审缺陷是否归零？ | G19: ✓
A20: 测试过程
A21: 1 | B21: 对于测试活动，有无制定测试计划，对测试方法、所需资源、测试对象和范围、测试进度安排进行明确？ | G21: ✓
A22: 2 | B22: 测试计划有无经过评审？ | G22: ✓
A23: 3 | B23: 实施测试前，有无建立测试规程对测试环境、运行场景、输入输出、实施步骤、准入准则、通过准则等予以文档化说明？ | G23: ✓
A24: 4 | B24: 对测试环境有无开展与目标环境的差异性分析？ | G24: ✓
A25: 5* | B25: 测试规程有无经过评审？ | G25: ✓
A26: 6* | B26: 实施测试前有无进行测试就绪状态确认？ | G26: ✓
A27: 7* | B27: 有无如实记录测试用例执行过程？对于有量值要求的指标，有无记录实测值？ | G27: ✓
A28: 8 | B28: 对于测试发现的缺陷有无进行标识、记录并形成问题报告单？ | G28: ✓
A29: 9 | B29: 对于测试缺陷，有无分析并确定原因，并制定纠正措施？ | G29: ✓
A30: 10 | B30: 对属于测试方法、准则及环境等因素的缺陷，有无修订测试规程并重新进行测试？ | G30: ✓
A31: 11 | B31: 对处理后的测试缺陷有无进行回归测试？ | G31: ✓
A32: 12* | B32: 对测试结果有无进行分析总结形成测试报告，并和利益相关方进行沟通确认？ | G32: ✓
... A34: 14* | B34: 测试缺陷有无归零？如未归零，有无明确的放行标准？ | G34: ✓
A36: 不符合项问题明细
A37: 问题ID | B37: 检查项 | C37: 问题描述 | F37: 严重程度 | G37: 责任人 | H37: 提交日期 | I37: 计划关闭日期 | J37: 纠正措施 | L37: 关闭
A38: 35 | B38: 5 | C38: 相关工作产品未完整覆盖本检查项要求的必要内容和适用场景，当前结果不能支撑该项要求已经全部落实。 | F38: 一般 | G38: 赵要浦 | H38: 2026-03-11 | I38: 2026-03-11 | J38: 补齐遗漏内容和适用场景，核对相关输入后组织复核，并保留复核结论。 | L38: 否

Sheet R032-审核验证与确认过程
B1: 过程/产品审核报告
B2: 编号：ZDPX-03046/0.0-QA-审核报告-032
B3: 项目名称 | D3: 相控阵数字样机软件 | H3: 所处阶段 | J3: 软件编码与单元测试阶段
B4: 审核对象（过程名称/产品名称） | F4: 审核验证与确认过程
B5: 审核人 | D5: 高蕾 | F5: 审核日期 | H5: 2026-03-11
B6: 审核依据 | D6: ZDPX-03046/0.0-QA-检查单-032
B7: 本次审核依据《验证与确认检查单》实施。经审核，发现1个不符合项。
B9: NC总数 | D9: 轻微 | F9: 一般 | H9: 严重
B10: =COUNTIF(B13:B13,"<>") | D10: =COUNTIF(F13:F13,"轻微") | F10: =COUNTIF(F13:F13,"一般") | H10: =COUNTIF(F13:F13,"严重")
B11: 不符合项问题（NC）列表
B12: 序号 | C12: 问题描述 | F12: 严重程度 | G12: 责任人 | H12: 提交日期 | I12: 计划关闭日期 | J12: 纠正措施
B13: 1 | C13: ='C032-审核验证与确认过程'!C38 | F13: ='C032-审核验证与确认过程'!F38 | G13: ='C032-审核验证与确认过程'!G38 | H13: ='C032-审核验证与确认过程'!H38 | I13: ='C032-审核验证与确认过程'!I38 | J13: ='C032-审核验证与确认过程'!J38
B15: 纠正措施验证情况：
B16: 已整改并验证通过

Sheet C033-审核需求开发与管理过程
A1: 需求开发与管理检查单
A2: 编号：ZDPX-03046/0.0-QA-检查单-033
A3: 项目名称 | C3: 相控阵数字样机软件 | F3: 当前阶段 | H3: 软件编码与单元测试阶段 | J3: 项目QA | L3: 高蕾
A4: 审核对象 | C4: 审核需求开发与管理过程 | F4: 产品标识 | H4: — | J4: 产品版本 | L4: —
A6: 序号 | B6: 审核内容 | G6: 是 | H6: 否 | I6: 不适用 | J6: 严重程度 | L6: 备注
A7: 需求开发与确认
A8: 1* | B8: 是否对顾客需求进行了开发并编制了顾客需求文档？（技术协议、软件研制任务书初稿、顾客需求列表等） | G8: ✓
A9: 2* | B9: 是否明确了本项目的需求提供者？ | G9: ✓
A10: 3 | B10: 对文档化的初始顾客需求，是否组织了需求研讨？ （软件研制任务书的研讨、技术协议的研讨等） | G10: ✓
A11: 4 | B11: 需求提供者及其他利益相关方有无参加顾客需求研讨？研讨活动有无留存记录？ | G11: ✓
A12: 5* | B12: 需求提供者、利益相关方和项目参与者对顾客需求有无达成共识？项目参与者对顾客需求有无作出承诺？（软件研制任务书的评审、合同流转签署等） | G12: ✓
A13: 6* | B13: 有无对系统或软件的运行方案和场景进行开发和定义，并体现在相应的文档中？（系统规格、软件需规、技术方案、运行方案等） | G13: ✓
A14: 7* | B14: 有无和利益相关方一起对运行方案和场景进行评审？ | G14: ✓
A15: 8 | B15: 产品和产品部件需求开发是否以顾客需求或系统分配需求（功能基线）作为输入？ | G15: ✓
A16: 9 | B16: 对产品和产品部件需求的开发，除功能需求外，有无包含性能、接口、可靠性、安全性等非功能需求的开发？ | G16: ✓
A17: 10 | B17: 产品和产品部件需求开发的结果是否文档化？（系统规格、软件需规） | G17: ✓
A18: 11* | B18: 有无对需求的必要性和充分性进行分析，并与利益相关方一起确认需求？（系统规格、软件需规的评审） | G18: ✓
A19: 12* | B19: 是否以通过评审、批准的软件需求规格说明作为软件设计的依据？ | G19: ✓
... A23: 16* | B23: 源代码是否通过了各级测试？ | G23: ✓
A24: 需求管理
A25: 17* | B25: 软件研制任务书评审通过后，是否建立了功能基线？ | H25: ✓ | J25: 严重 | K25: 必要内容覆盖不完整
A26: 18* | B26: 软件需规评审通过后，是否建立了分配基线？ | G26: ✓
A27: 19* | B27: 是否按照体系规定的追踪关系，在生成的各文档中都填写了正向和逆向追踪表。 | G27: ✓
A28: 20 | B28: 项目负责人发现需求管理问题时，是否依据《项目监控过程》的要求填写了“项目问题跟踪表”。 | G28: ✓
A29: 21 | B29: 发现的需求管理问题是否在项目工作例会上通报，并跟踪直至问题关闭。 | G29: ✓
A30: 22 | B30: 项目负责人是否在项目阶段总结、里程碑评审前形成需求管理情况工作报告？ | G30: ✓
A31: 23* | B31: 顾客需求的变更是否得到合同甲方或用户的认可？ | G31: ✓
A32: 24* | B32: 需求发生变更时，是否填写了变更申请单，说明了需变更的内容并进行了影响域分析？ | G32: ✓
A33: 25* | B33: 变更申请是否经过了评估，并得到了批准？批准的权限是否正确？ | G33: ✓
A34: 26 | B34: 需求发生变更时，是否更新了受影响的各项工作产品？ | G34: ✓
A35: 27 | B35: 需求变更完成后，是否通过评审、测试等方式对变更情况进行确认，并填写了变更报告 | G35: ✓
A36: 28 | B36: 需求变更完成后是否更新了受控库中的功能基线或分配基线并发布？ | G36: ✓
A37: 29* | B37: 当变更影响对外承诺时，是否由公司软件配置控制委员会进行了审批？ | G37: ✓
A39: 不符合项问题明细
A40: 问题ID | B40: 检查项 | C40: 问题描述 | F40: 严重程度 | G40: 责任人 | H40: 提交日期 | I40: 计划关闭日期 | J40: 纠正措施 | L40: 关闭
A41: 36 | B41: 17 | C41: 相关工作产品未完整覆盖本检查项要求的必要内容和适用场景，当前结果不能支撑该项要求已经全部落实。 | F41: 严重 | G41: 赵要浦 | H41: 2026-03-11 | I41: 2026-03-11 | J41: 补齐遗漏内容和适用场景，核对相关输入后组织复核，并保留复核结论。 | L41: 否

Sheet R033-审核需求开发与管理过程
B1: 过程/产品审核报告
B2: 编号：ZDPX-03046/0.0-QA-审核报告-033
B3: 项目名称 | D3: 相控阵数字样机软件 | H3: 所处阶段 | J3: 软件编码与单元测试阶段
B4: 审核对象（过程名称/产品名称） | F4: 审核需求开发与管理过程
B5: 审核人 | D5: 高蕾 | F5: 审核日期 | H5: 2026-03-11
B6: 审核依据 | D6: ZDPX-03046/0.0-QA-检查单-033
B7: 本次审核依据《需求开发与管理检查单》实施。经审核，发现1个不符合项。
B9: NC总数 | D9: 轻微 | F9: 一般 | H9: 严重
B10: =COUNTIF(B13:B13,"<>") | D10: =COUNTIF(F13:F13,"轻微") | F10: =COUNTIF(F13:F13,"一般") | H10: =COUNTIF(F13:F13,"严重")
B11: 不符合项问题（NC）列表
B12: 序号 | C12: 问题描述 | F12: 严重程度 | G12: 责任人 | H12: 提交日期 | I12: 计划关闭日期 | J12: 纠正措施
B13: 1 | C13: ='C033-审核需求开发与管理过程'!C41 | F13: ='C033-审核需求开发与管理过程'!F41 | G13: ='C033-审核需求开发与管理过程'!G41 | H13: ='C033-审核需求开发与管理过程'!H41 | I13: ='C033-审核需求开发与管理过程'!I41 | J13: ='C033-审核需求开发与管理过程'!J41
B15: 纠正措施验证情况：
B16: 已整改并验证通过

Sheet C034-审核配置管理过程-阶段末
A1: 配 置 管 理 检 查 单
A2: 编号：ZDPX-03046/0.0-QA-检查单-034
A3: 项目名称 | C3: 相控阵数字样机软件 | F3: 当前阶段 | H3: 软件编码与单元测试阶段 | J3: 项目QA | L3: 高蕾
A4: 审核对象 | C4: 审核配置管理过程-阶段末 | F4: 产品标识 | H4: — | J4: 产品版本 | L4: —
A6: 序号 | B6: 审核内容 | G6: 是 | H6: 否 | I6: 不适用 | J6: 严重程度 | L6: 备注
A7: 通用检查项
A8: 1 | B8: 是否为项目建立了受控库和开发库？ | G8: ✓
A9: 2* | B9: 是否按计划对配置项进行了受控管理？ | G9: ✓
A10: 3 | B10: 配置项的出入库单填写是否正确？ | G10: ✓
A11: 4 | B11: 受控库中配置项和基线的标识是否遵循了标识规则？ | G11: ✓
A12: 5* | B12: 受控库中基线的组成配置项是否与配置管理计划一致？ | G12: ✓
A13: 6 | B13: 受控库中每个基线版本是否都对应基线发布单？ | G13: ✓
A14: 7 | B14: 基线的建立和和变更情况是否通报给所有受影响的组和个人？ | G14: ✓
A15: 8 | B15: 配置项出入库、基线发布是否都经过了正确的审批？ | G15: ✓
A16: 9 | B16: 受控库是否按配置管理计划中的备份策略进行了备份？ | G16: ✓
A17: 10 | B17: 开发库的使用与配置管理计划要求是否一致？ | G17: ✓
A18: 11 | B18: 环境配置项有无受控管理？ | G18: ✓
A19: 12* | B19: 提交变更申请时，是否具体描述了需变更的内容，并进行了影响域分析？ | G19: ✓
... A29: 22 | B29: 配置管理报告内容是否完整 | G29: ✓
A31: 不符合项问题明细
A32: 问题ID | B32: 检查项 | C32: 问题描述 | F32: 严重程度 | G32: 责任人 | H32: 提交日期 | I32: 计划关闭日期 | J32: 纠正措施 | L32: 关闭
A33: 本次审核未发现不符合项。

Sheet R034-审核配置管理过程-阶段末
B1: 过程/产品审核报告
B2: 编号：ZDPX-03046/0.0-QA-审核报告-034
B3: 项目名称 | D3: 相控阵数字样机软件 | H3: 所处阶段 | J3: 软件编码与单元测试阶段
B4: 审核对象（过程名称/产品名称） | F4: 审核配置管理过程-阶段末
B5: 审核人 | D5: 高蕾 | F5: 审核日期 | H5: 2026-03-11
B6: 审核依据 | D6: ZDPX-03046/0.0-QA-检查单-034
B7: 本次审核依据《配 置 管 理 检 查 单》实施。经审核，未发现不符合项。
B9: NC总数 | D9: 轻微 | F9: 一般 | H9: 严重
B10: =0 | D10: =0 | F10: =0 | H10: =0
B11: 不符合项问题（NC）列表
B12: 序号 | C12: 问题描述 | F12: 严重程度 | G12: 责任人 | H12: 提交日期 | I12: 计划关闭日期 | J12: 纠正措施
B13: 本次审核未发现不符合项。
B15: 纠正措施验证情况：
B16: 不适用

Sheet C035-审核项目监控-阶段
A1: 项目监控检查单
A2: 编号：ZDPX-03046/0.0-QA-检查单-035
A3: 项目名称 | C3: 相控阵数字样机软件 | F3: 当前阶段 | H3: 软件编码与单元测试阶段 | J3: 项目QA | L3: 高蕾
A4: 审核对象 | C4: 审核项目监控-阶段 | F4: 产品标识 | H4: — | J4: 产品版本 | L4: —
A6: 序号 | B6: 审核内容 | G6: 是 | H6: 否 | I6: 不适用 | J6: 严重程度 | L6: 备注
A7: 通用检查项
A8: 1 | B8: 本阶段的任务是否以任务分配表的形式分配到个人？ | G8: ✓
A9: 2 | B9: 项目组成员是否按时填写个人工作报告，记录个人完成任务的情况、工作量等信息？ | G9: ✓
A10: 3* | B10: 在每个跟踪节点，项目负责人是否对项目进度和工作量进行汇总，并与计划值进行比较？对于超过阈值的偏差是否进行了分析？ | G10: ✓
A11: 4 | B11: 每当工作产品完成时，项目负责人是否统计工作产品实际规模，并与计划值进行比较？对于超过阈值的偏差是否进行了分析？ | G11: ✓
A12: 5 | B12: 是否依据利益相关方参与计划，及时记录利益相关方参与情况？对出现的偏差有无进行分析？ | G12: ✓
A13: 6* | B13: 是否按体系要求对识别出的风险进行跟踪？ | G13: ✓
A14: 7* | B14: 当识别出新风险时，是否更新项目风险表并进行跟踪？ | G14: ✓
A15: 8 | B15: 是否对资源计划进行了跟踪？对出现的偏差有无进行分析？ | G15: ✓
A16: 9 | B16: 是否对培训计划进行了跟踪？对出现的偏差有无进行分析？ | G16: ✓
A17: 10 | B17: 项目负责人对项目跟踪过程中发现的问题是否及时记录，并制定纠正措施？ | G17: ✓
A18: 11 | B18: 纠正措施是否明确了责任人、验证人？ | G18: ✓
A19: 12* | B19: 当纠正措施会影响到对外承诺时，是否与利益相关方对纠正措施进行了评审？ | G19: ✓
... A23: 16 | B23: 是否定期（双周、阶段末和里程碑）对质量工作进行总结，形成质量审核工作报告？ | G23: ✓
A24: 17 | B24: 是否定期（阶段末和里程碑）对配管工作进行总结，形成配置管理工作报告？ | H24: ✓ | J24: 一般 | K24: 必要内容覆盖不完整
A25: 18 | B25: 是否定期（阶段末和里程碑）对需求管理工作进行总结，形成需求管理情况工作报告？ | G25: ✓
A26: 19* | B26: 项目负责人是否定期（双周、阶段末和里程碑）将工作进展及策划参数跟踪情况、问题及风险跟踪情况、偏差处理措施等进行汇总，形成项目进展报告？ | G26: ✓
A27: 20 | B27: 项目进展报告是否上报给项目总监，并通报给项目组人员？ | G27: ✓
A28: 21 | B28: 项目例会中是否对进展报告进行了交流，并对问题、风险、偏差等进行了讨论？ | G28: ✓
A29: 22 | B29: 项目例会有无形成会议纪要？ | G29: ✓
A30: 23* | B30: 是否按计划实施里程碑评审？ | G30: ✓
A31: 24 | B31: 里程碑评审参会人员是否符合体系要求？ | G31: ✓
A32: 25* | B32: 里程碑评审会的材料是否准备齐全？ | G32: ✓
A33: 26 | B33: 里程碑评审是否对评审节点前的项目进展情况、规模、进度、工作量、问题和风险等的跟踪情况进行了分析并标识出偏差。 | G33: ✓
A34: 27 | B34: 对于超出阈值的偏差是否分析了原因，并提出相应的措施 | H34: ✓ | J34: 一般 | K34: 必要内容覆盖不完整
A35: 28 | B35: 是否对新识别的问题制定了纠正措施 | G35: ✓
A36: 29* | B36: 里程碑评审后是否形成评审报告，并指定负责人处理评审意见。 | G36: ✓
A37: 30 | B37: 对评审意见的处理有无进行跟踪，直到形成闭环 | G37: ✓
A38: 31 | B38: 需对软件开发计划进行变更时，是否按要求办理了变更审批手续 | G38: ✓
A39: 32 | B39: 是否按规程修订项目软件开发计划及相关文档 | G39: ✓
A40: 33* | B40: 对外部承诺的变更是否经公司CCB的批准 | G40: ✓
A41: 34 | B41: 是否有通知受影响的组和个人的记录 | G41: ✓
A43: 不符合项问题明细
A44: 问题ID | B44: 检查项 | C44: 问题描述 | F44: 严重程度 | G44: 责任人 | H44: 提交日期 | I44: 计划关闭日期 | J44: 纠正措施 | L44: 关闭
A45: 37 | B45: 17 | C45: 相关工作产品未完整覆盖本检查项要求的必要内容和适用场景，当前结果不能支撑该项要求已经全部落实。 | F45: 一般 | G45: 赵要浦 | H45: 2026-03-11 | I45: 2026-03-11 | J45: 补齐遗漏内容和适用场景，核对相关输入后组织复核，并保留复核结论。 | L45: 否
...

Sheet R035-审核项目监控-阶段
B1: 过程/产品审核报告
B2: 编号：ZDPX-03046/0.0-QA-审核报告-035
B3: 项目名称 | D3: 相控阵数字样机软件 | H3: 所处阶段 | J3: 软件编码与单元测试阶段
B4: 审核对象（过程名称/产品名称） | F4: 审核项目监控-阶段
B5: 审核人 | D5: 高蕾 | F5: 审核日期 | H5: 2026-03-11
B6: 审核依据 | D6: ZDPX-03046/0.0-QA-检查单-035
B7: 本次审核依据《项目监控检查单》实施。经审核，发现2个不符合项。
B9: NC总数 | D9: 轻微 | F9: 一般 | H9: 严重
B10: =COUNTIF(B13:B14,"<>") | D10: =COUNTIF(F13:F14,"轻微") | F10: =COUNTIF(F13:F14,"一般") | H10: =COUNTIF(F13:F14,"严重")
B11: 不符合项问题（NC）列表
B12: 序号 | C12: 问题描述 | F12: 严重程度 | G12: 责任人 | H12: 提交日期 | I12: 计划关闭日期 | J12: 纠正措施
B13: 1 | C13: ='C035-审核项目监控-阶段'!C45 | F13: ='C035-审核项目监控-阶段'!F45 | G13: ='C035-审核项目监控-阶段'!G45 | H13: ='C035-审核项目监控-阶段'!H45 | I13: ='C035-审核项目监控-阶段'!I45 | J13: ='C035-审核项目监控-阶段'!J45
B14: 2 | C14: ='C035-审核项目监控-阶段'!C46 | F14: ='C035-审核项目监控-阶段'!F46 | G14: ='C035-审核项目监控-阶段'!G46 | H14: ='C035-审核项目监控-阶段'!H46 | I14: ='C035-审核项目监控-阶段'!I46 | J14: ='C035-审核项目监控-阶段'!J46
B16: 纠正措施验证情况：
B17: 已整改并验证通过；已整改并验证通过

Sheet C036-审核测量与绩效管理-阶段
A1: 测量与绩效管理检查单
A2: 编号：ZDPX-03046/0.0-QA-检查单-036
A3: 项目名称 | C3: 相控阵数字样机软件 | F3: 当前阶段 | H3: 软件编码与单元测试阶段 | J3: 项目QA | L3: 高蕾
A4: 审核对象 | C4: 审核测量与绩效管理-阶段 | F4: 产品标识 | H4: — | J4: 产品版本 | L4: —
A6: 序号 | B6: 审核内容 | G6: 是 | H6: 否 | I6: 不适用 | J6: 严重程度 | L6: 备注
A7: 通用检查项
A8: 1* | B8: 是否建立了项目的测量目标？ | G8: ✓
A9: 2 | B9: 是否根据测量目标确定了项目所要使用的测量项？ | G9: ✓
A10: 3 | B10: 是否指定了测量分析的负责人？ | G10: ✓
A11: 4 | B11: 是否确定了测量数据的存储方式？ | G11: ✓
A12: 5 | B12: 是否明确了项目测量项的采集时机、采集方法、采集位置及采集人？ | G12: ✓
A13: 6 | B13: 是否指明了对测量数据的分析方法、表达方式等？ | G13: ✓
A14: 7 | B14: 是否明确了测量数据分析结果的交流时机、交流方式？ | H14: ✓ | J14: 一般 | K14: 必要内容覆盖不完整
A15: 8 | B15: 是否制定了项目的测量与分析计划？并对测量分析计划进行了评审？ | H15: ✓ | J15: 一般 | K15: 必要内容覆盖不完整
A16: 9 | B16: 当项目有新增测量项时，是否经过软件工程过程组的审批？ | G16: ✓
A17: 10 | B17: 是否按照测量与分析计划，在规定的时间和采集点收集测量数据？ | G17: ✓
A18: 11 | B18: 是否将采集到的数据（需要时进行预处理）存入指定的数据分析工具平台？ | G18: ✓
A19: 12 | B19: 是否在计划时间点对采集到的测量数据进行分析？ | G19: ✓
A20: 13 | B20: 是否将分析结果汇总形成测量与分析报告？ | G20: ✓
A21: 14 | B21: 是否与项目组、利益相关方（必要时）交流了测量数据的分析结果？ | G21: ✓
A22: 15 | B22: 项目实施过程中，测量相关的数据和文档有无得到有效控制？ | G22: ✓
A24: 不符合项问题明细
A25: 问题ID | B25: 检查项 | C25: 问题描述 | F25: 严重程度 | G25: 责任人 | H25: 提交日期 | I25: 计划关闭日期 | J25: 纠正措施 | L25: 关闭
A26: 39 | B26: 7 | C26: 相关工作产品未完整覆盖本检查项要求的必要内容和适用场景，当前结果不能支撑该项要求已经全部落实。 | F26: 一般 | G26: 赵要浦 | H26: 2026-03-11 | I26: 2026-03-11 | J26: 补齐遗漏内容和适用场景，核对相关输入后组织复核，并保留复核结论。 | L26: 否
A27: 40 | B27: 8 | C27: 相关工作产品未完整覆盖本检查项要求的必要内容和适用场景，当前结果不能支撑该项要求已经全部落实。 | F27: 一般 | G27: 赵要浦 | H27: 2026-03-11 | I27: 2026-03-11 | J27: 补齐遗漏内容和适用场景，核对相关输入后组织复核，并保留复核结论。 | L27: 否

Sheet R036-审核测量与绩效管理-阶段
B1: 过程/产品审核报告
B2: 编号：ZDPX-03046/0.0-QA-审核报告-036
B3: 项目名称 | D3: 相控阵数字样机软件 | H3: 所处阶段 | J3: 软件编码与单元测试阶段
B4: 审核对象（过程名称/产品名称） | F4: 审核测量与绩效管理-阶段
B5: 审核人 | D5: 高蕾 | F5: 审核日期 | H5: 2026-03-11
B6: 审核依据 | D6: ZDPX-03046/0.0-QA-检查单-036
B7: 本次审核依据《测量与绩效管理检查单》实施。经审核，发现2个不符合项。
B9: NC总数 | D9: 轻微 | F9: 一般 | H9: 严重
B10: =COUNTIF(B13:B14,"<>") | D10: =COUNTIF(F13:F14,"轻微") | F10: =COUNTIF(F13:F14,"一般") | H10: =COUNTIF(F13:F14,"严重")
B11: 不符合项问题（NC）列表
B12: 序号 | C12: 问题描述 | F12: 严重程度 | G12: 责任人 | H12: 提交日期 | I12: 计划关闭日期 | J12: 纠正措施
B13: 1 | C13: ='C036-审核测量与绩效管理-阶段'!C26 | F13: ='C036-审核测量与绩效管理-阶段'!F26 | G13: ='C036-审核测量与绩效管理-阶段'!G26 | H13: ='C036-审核测量与绩效管理-阶段'!H26 | I13: ='C036-审核测量与绩效管理-阶段'!I26 | J13: ='C036-审核测量与绩效管理-阶段'!J26
B14: 2 | C14: ='C036-审核测量与绩效管理-阶段'!C27 | F14: ='C036-审核测量与绩效管理-阶段'!F27 | G14: ='C036-审核测量与绩效管理-阶段'!G27 | H14: ='C036-审核测量与绩效管理-阶段'!H27 | I14: ='C036-审核测量与绩效管理-阶段'!I27 | J14: ='C036-审核测量与绩效管理-阶段'!J27
B16: 纠正措施验证情况：
B17: 已整改并验证通过；已整改并验证通过

Sheet C038-相控阵数字样机软件单元测试报告
A1: 软件测试报告检查单
A2: 编号：ZDPX-03046/0.0-QA-检查单-038
A3: 项目名称 | C3: 相控阵数字样机软件 | F3: 当前阶段 | H3: 软件编码与单元测试阶段 | J3: 项目QA | L3: 高蕾
A4: 审核对象 | C4: 相控阵数字样机软件单元测试报告 | F4: 产品标识 | H4: ZDPX03046/0.0-DCBG | J4: 产品版本 | L4: V1.0
A6: 序号 | B6: 审核内容 | G6: 是 | H6: 否 | I6: 不适用 | J6: 严重程度 | L6: 备注
A7: 通用检查项
A8: 1 | B8: 是否完整、准确记录了软件的完整标识？ | G8: ✓
A9: 2 | B9: 是否正确记录了本文档所适用对象的用途？ | G9: ✓
A10: 3 | B10: 是否完整、准确记录了本测试报告的依据？ | G10: ✓
A11: 4 | B11: 是否准确地说明了本测试报告的级别（单元测试、集成测试、合格性测试）？ | G11: ✓
A12: 5 | B12: 是否完整、准确地说明了测试过程？ | G12: ✓
A13: 6* | B13: 是否对被测软件有总体评估？ | G13: ✓
A14: 7* | B14: 是否完整、准确的记录了测试用例执行结果？ | G14: ✓
A15: 8* | B15: 是否有完整的问题报告单？ | H15: ✓ | J15: 严重 | K15: 必要内容覆盖不完整
A17: 不符合项问题明细
A18: 问题ID | B18: 检查项 | C18: 问题描述 | F18: 严重程度 | G18: 责任人 | H18: 提交日期 | I18: 计划关闭日期 | J18: 纠正措施 | L18: 关闭
A19: 41 | B19: 8 | C19: 相关工作产品未完整覆盖本检查项要求的必要内容和适用场景，当前结果不能支撑该项要求已经全部落实。 | F19: 严重 | G19: 赵要浦 | H19: 2026-03-11 | I19: 2026-03-11 | J19: 补齐遗漏内容和适用场景，核对相关输入后组织复核，并保留复核结论。 | L19: 否

Sheet R038-相控阵数字样机软件单元测试报告
B1: 过程/产品审核报告
B2: 编号：ZDPX-03046/0.0-QA-审核报告-038
B3: 项目名称 | D3: 相控阵数字样机软件 | H3: 所处阶段 | J3: 软件编码与单元测试阶段
B4: 审核对象（过程名称/产品名称） | F4: 相控阵数字样机软件单元测试报告
B5: 审核人 | D5: 高蕾 | F5: 审核日期 | H5: 2026-03-11
B6: 审核依据 | D6: ZDPX-03046/0.0-QA-检查单-038
B7: 本次审核依据《软件测试报告检查单》实施。经审核，发现1个不符合项。
B9: NC总数 | D9: 轻微 | F9: 一般 | H9: 严重
B10: =COUNTIF(B13:B13,"<>") | D10: =COUNTIF(F13:F13,"轻微") | F10: =COUNTIF(F13:F13,"一般") | H10: =COUNTIF(F13:F13,"严重")
B11: 不符合项问题（NC）列表
B12: 序号 | C12: 问题描述 | F12: 严重程度 | G12: 责任人 | H12: 提交日期 | I12: 计划关闭日期 | J12: 纠正措施
B13: 1 | C13: ='C038-相控阵数字样机软件单元测试报告'!C19 | F13: ='C038-相控阵数字样机软件单元测试报告'!F19 | G13: ='C038-相控阵数字样机软件单元测试报告'!G19 | H13: ='C038-相控阵数字样机软件单元测试报告'!H19 | I13: ='C038-相控阵数字样机软件单元测试报告'!I19 | J13: ='C038-相控阵数字样机软件单元测试报告'!J19
B15: 纠正措施验证情况：
B16: 已整改并验证通过

Sheet _计算
A1: 流水号 | B1: 审核对象 | C1: 问题序号 | D1: NC类型 | E1: 问题描述 | F1: 严重程度 | G1: 是否关闭 | H1: 归组日期 | I1: 节点类型 | J1: 审核日期
A2: 32 | B2: ='R032-审核验证与确认过程'!F4 | C2: ='R032-审核验证与确认过程'!B13 | D2: VV | E2: ='R032-审核验证与确认过程'!C13 | F2: ='R032-审核验证与确认过程'!F13 | G2: 否 | H2: 2026-03-11 | I2: 阶段 | J2: 2026-03-11
A3: 33 | B3: ='R033-审核需求开发与管理过程'!F4 | C3: ='R033-审核需求开发与管理过程'!B13 | D3: RDM | E3: ='R033-审核需求开发与管理过程'!C13 | F3: ='R033-审核需求开发与管理过程'!F13 | G3: 否 | H3: 2026-03-11 | I3: 阶段 | J3: 2026-03-11
A4: 35 | B4: ='R035-审核项目监控-阶段'!F4 | C4: ='R035-审核项目监控-阶段'!B13 | D4: PMC | E4: ='R035-审核项目监控-阶段'!C13 | F4: ='R035-审核项目监控-阶段'!F13 | G4: 否 | H4: 2026-03-11 | I4: 阶段 | J4: 2026-03-11
A5: 35 | B5: ='R035-审核项目监控-阶段'!F4 | C5: ='R035-审核项目监控-阶段'!B14 | D5: PMC | E5: ='R035-审核项目监控-阶段'!C14 | F5: ='R035-审核项目监控-阶段'!F14 | G5: 否 | H5: 2026-03-11 | I5: 阶段 | J5: 2026-03-11
A6: 36 | B6: ='R036-审核测量与绩效管理-阶段'!F4 | C6: ='R036-审核测量与绩效管理-阶段'!B13 | D6: MPM | E6: ='R036-审核测量与绩效管理-阶段'!C13 | F6: ='R036-审核测量与绩效管理-阶段'!F13 | G6: 否 | H6: 2026-03-11 | I6: 阶段 | J6: 2026-03-11
A7: 36 | B7: ='R036-审核测量与绩效管理-阶段'!F4 | C7: ='R036-审核测量与绩效管理-阶段'!B14 | D7: MPM | E7: ='R036-审核测量与绩效管理-阶段'!C14 | F7: ='R036-审核测量与绩效管理-阶段'!F14 | G7: 否 | H7: 2026-03-11 | I7: 阶段 | J7: 2026-03-11
A8: 38 | B8: ='R038-相控阵数字样机软件单元测试报告'!F4 | C8: ='R038-相控阵数字样机软件单元测试报告'!B13 | D8: 工作产品 | E8: ='R038-相控阵数字样机软件单元测试报告'!C13 | F8: ='R038-相控阵数字样机软件单元测试报告'!F13 | G8: 否 | H8: 2026-03-11 | I8: 阶段 | J8: 2026-03-11
