Workbook

Sheet 质量审核工作报告2025.8.25
A1: 质量审核工作报告
A2: 编号：ZDPX-2022020/0.0-QA-质量报告-002
A3: 项目名称 | B3: 测控体系辅助业务系统
A4: 报告阶段 | B4: 软件需求分析 | D4: 报告起止日期 | F4: 2025.7.9-2025.8.25 | J4: 项目QA | K4: 高蕾
A5: 审核情况汇总
A6: 审核过程/产品名称 | C6: ='005产品审核报告-测量与分析计划2025.7.15'!F4 -> 《软件测量与分析计划》 | K6: 审核时间 | L6: ='005产品审核报告-测量与分析计划2025.7.15'!H5 -> 45853
A7: 不符合项列表 | J7: NC类型 | K7: 严重程度 | L7: 是否关闭
A8: =IF('005产品审核报告-测量与分析计划2025.7.15'!B13="","",'005产品审核报告-测量与分析计划2025.7.15'!B13) -> 1 | B8: =IF('005产品审核报告-测量与分析计划2025.7.15'!C13="","",'005产品审核报告-测量与分析计划2025.7.15'!C13) -> 表2测量工作相关人员中，测试人员应为吴丹和李德馨 | J8: 工作产品 | K8: =IF('005产品审核报告-测量与分析计划2025.7.15'!F13="","",'005产品审核报告-测量与分析计划2025.7.15'!F13) -> 一般 | L8: 是
A9: =IF('005产品审核报告-测量与分析计划2025.7.15'!B14="","",'005产品审核报告-测量与分析计划2025.7.15'!B14) -> 2 | B9: =IF('005产品审核报告-测量与分析计划2025.7.15'!C14="","",'005产品审核报告-测量与分析计划2025.7.15'!C14) -> 表8中部分阶段的测量时机和开发计划中的进度安排不一 | J9: 工作产品 | K9: =IF('005产品审核报告-测量与分析计划2025.7.15'!F14="","",'005产品审核报告-测量与分析计划2025.7.15'!F14) -> 一般 | L9: 是
A10: 审核过程/产品名称 | C10: ='006产品审核报告-质量保证计划2025.7.15'!F4 -> 《软件质量保证计划》 | K10: 审核时间 | L10: ='006产品审核报告-质量保证计划2025.7.15'!H5 -> 45853
A11: 不符合项列表 | J11: NC类型 | K11: 严重程度 | L11: 是否关闭
A12: =IF('006产品审核报告-质量保证计划2025.7.15'!B13="","",'006产品审核报告-质量保证计划2025.7.15'!B13) -> 1 | B12: =IF('006产品审核报告-质量保证计划2025.7.15'!C13="","",'006产品审核报告-质量保证计划2025.7.15'!C13) -> 表5阶段划分，缺少出厂检验和验收交付阶段 | J12: 工作产品 | K12: =IF('006产品审核报告-质量保证计划2025.7.15'!K13,"",'006产品审核报告-质量保证计划2025.7.15'!F13) -> 严重 | L12: 是
A13: =IF('006产品审核报告-质量保证计划2025.7.15'!B14="","",'006产品审核报告-质量保证计划2025.7.15'!B14) -> 2 | B13: =IF('006产品审核报告-质量保证计划2025.7.15'!C14="","",'006产品审核报告-质量保证计划2025.7.15'!C14) -> 6.4节，产品审核对象中有配置项测试计划、合格性测试说明、合格性测试报告，与上下文不一致，另外缺少技术说明书、软件使用说明书等。 | J13: 工作产品 | K13: =IF('006产品审核报告-质量保证计划2025.7.15'!K14,"",'006产品审核报告-质量保证计划2025.7.15'!F14) -> 一般 | L13: 是
A14: 审核过程/产品名称 | C14: ='007产品审核报告-配置管理计划2025.7.15'!F4 -> 《配置管理计划》 | K14: 审核时间 | L14: ='007产品审核报告-配置管理计划2025.7.15'!H5 -> 45853
A15: 不符合项列表 | J15: NC类型 | K15: 严重程度 | L15: 是否关闭
A16: =IF('007产品审核报告-配置管理计划2025.7.15'!B13="","",'007产品审核报告-配置管理计划2025.7.15'!B13) -> 1 | B16: =IF('007产品审核报告-配置管理计划2025.7.15'!C13="","",'007产品审核报告-配置管理计划2025.7.15'!C13) -> 4.1节中，通过配置项测试后的源代码版本应是V0.1.0 | J16: 工作产品 | K16: =IF('007产品审核报告-配置管理计划2025.7.15'!F13="","",'007产品审核报告-配置管理计划2025.7.15'!F13) -> 一般 | L16: 是
A17: =IF('007产品审核报告-配置管理计划2025.7.15'!B14="","",'007产品审核报告-配置管理计划2025.7.15'!B14) -> 2 | B17: =IF('007产品审核报告-配置管理计划2025.7.15'!C14="","",'007产品审核报告-配置管理计划2025.7.15'!C14) -> 表3配置项清单中遗漏了技术说明书和培训教材 | J17: 工作产品 | K17: =IF('007产品审核报告-配置管理计划2025.7.15'!F14="","",'007产品审核报告-配置管理计划2025.7.15'!F14) -> 一般 | L17: 是
A18: 审核过程/产品名称 | C18: ='008产品审核报告-软件开发计划2025.7.15'!F4 -> 《软件开发计划》 | K18: 审核时间 | L18: ='008产品审核报告-软件开发计划2025.7.15'!H5 -> 45853
A19: 不符合项列表 | J19: NC类型 | K19: 严重程度 | L19: 是否关闭
A20: =IF('008产品审核报告-软件开发计划2025.7.15'!B13="","",'008产品审核报告-软件开发计划2025.7.15'!B13) -> 1 | B20: =IF('008产品审核报告-软件开发计划2025.7.15'!C13="","",'008产品审核报告-软件开发计划2025.7.15'!C13) -> 表3-1项目文档要求与软件研制任务书不一致，缺少培训教材 | J20: 工作产品 | K20: =IF('008产品审核报告-软件开发计划2025.7.15'!F13="","",'008产品审核报告-软件开发计划2025.7.15'!F13) -> 一般 | L20: 是
A21: =IF('008产品审核报告-软件开发计划2025.7.15'!B14="","",'008产品审核报告-软件开发计划2025.7.15'!B14) -> 2 | B21: =IF('008产品审核报告-软件开发计划2025.7.15'!C14="","",'008产品审核报告-软件开发计划2025.7.15'!C14) -> 5.2.6出厂所检验的工作内容与本项目合同要求的不一致。 | J21: 工作产品 | K21: =IF('008产品审核报告-软件开发计划2025.7.15'!F14="","",'008产品审核报告-软件开发计划2025.7.15'!F14) -> 一般 | L21: 是
A22: 双周汇总统计： | C22: 本双周审核的实践域包括：项目策划、测量与绩效管理、项目监控； 审核的工作产品包括：软件开发计划、软件测量与分析计划、软件质量保证计划、软件配置管理计划
A23: 起始时间 | C23: 45847 | G23: 结束时间 | I23: 45861
A24: 产品NC统计
A25: 产品NC总数 | C25: 关闭情况 | G25: 按严重程度分布情况
A26: =COUNTIF(J8:J21,"工作产品") -> 8 | C26: 未关闭的产品NC数 | E26: 产品NC关闭率 | I26: 轻微 | K26: 一般 | L26: 严重
C27: =COUNTIFS(J8:J21,"工作产品",L8:L21,"=否") -> 0 | E27: =(A26-C27)/A26 -> 1 | G27: NC数 | I27: =COUNTIFS(J8:J21,"工作产品",K8:K21,"=轻微") -> 0 | K27: =COUNTIFS(J8:J21,"工作产品",K8:K21,"=一般") -> 7 | L27: =COUNTIFS(J8:J21,"工作产品",K8:K21,"=严重") -> 1
G28: 所占比例 | I28: =I27/A26 -> 0 | K28: =K27/A26 -> 0.875 | L28: =L27/A26 -> 0.125
A29: 过程NC统计
A30: 过程NC总数 | C30: 关闭情况 | G30: 按严重程度分布情况
A31: =SUM(COUNTIF(J8:J21,{"RDM","PP","PMC","CM","MT","MPM","VV","II"})) -> 0 | C31: 未关闭的过程NC数 | E31: 过程NC关闭率 | I31: 轻微 | K31: 一般 | L31: 严重
C32: — | E32: — | G32: NC数 | I32: =SUM(COUNTIFS(J8:J21,{"RDM","PP","PMC","CM","MT","MPM","VV","II"},K8:K21,"=轻微")) -> 0 | K32: =SUM(COUNTIFS(J8:J21,{"RDM","PP","PMC","CM","MT","MPM","VV","II"},K8:K21,"=一般")) -> 0 | L32: =SUM(COUNTIFS(J8:J21,{"RDM","PP","PMC","CM","MT","MPM","VV","II"},K8:K21,"=严重")) -> 0
G33: 所占比例 | I33: — | K33: — | L33: —
A34: 过程及产品NC占比统计
A35: NC分布情况 | C35: RDM | D35: PP | E35: PMC | F35: CM | G35: MT | H35: MPM | I35: VV | J35: II（双周） | K35: 工作产品 | L35: 总计
A36: NC数 | C36: =COUNTIF(J9:J22,"=RDM") -> 0 | D36: =COUNTIF(J9:J22,"=PP") -> 0 | E36: =COUNTIF(J9:J22,"=PMC") -> 0 | F36: =COUNTIF(J9:J22,"=CM") -> 0 | G36: =COUNTIF(J9:J22,"=MT") -> 0 | H36: =COUNTIF(J9:J22,"=MPM") -> 0 | I36: =COUNTIF(J9:J22,"=VV") -> 0 | J36: =COUNTIF(J9:J22,"=II") -> 0 | K36: =COUNTIF(J8:J22,"=工作产品") -> 8 | L36: =SUM(C36:K36) -> 8
A37: 所占比例 | C37: =C36/L36 -> 0 | D37: =D36/L36 -> 0 | E37: =E36/L36 -> 0 | F37: =F36/L36 -> 0 | G37: =G36/L36 -> 0 | H37: =H36/L36 -> 0 | I37: =I36/L36 -> 0 | J37: =J36/L36 -> 0 | K37: =K36/L36 -> 1 | L37: ─
A38: 数据分析
A39: 本双周共发现8个不符合项，主要分布在工作产品中，无严重不符合项。文档编写出现的小问题较多，相关责任人需提高责任心，减少文档编写中的低级错误。
A40: 审核过程/产品名称 | C40: ='012配置管理审核报告-2025.7.31 (月)'!F4 -> 配置管理 | K40: 审核时间 | L40: ='012配置管理审核报告-2025.7.31 (月)'!H5 -> 45869
...

Sheet 005产品审核报告-测量与分析计划2025.7.15
B1: 过程/产品审核报告
B2: 编号：ZDPX-2022020/0.0-QA-审核报告-005
B3: 项目名称 | C3: 测控体系辅助业务系统 | H3: 所处阶段 | I3: 软件需求分析
B4: 审核对象（过程名称/产品名称） | F4: 《软件测量与分析计划》
B5: 审核人 | C5: 高蕾 | F5: 审核日期 | H5: 45853
B6: 审核依据 | C6: ZDPX-2022020/0.0-QA-检查单-005
B7: 审核内容概述：
B8: 审核内容概述： 本次审核的产品为测量与分析计划，审核内容包括： 1）编写的规范性； 2）与其它相关文档的一致性； 3）内容的完整性和正确性； 4）上下文的一致性； 5）对模板的符合性。 经审核，发现2个不符合项。
B9: 按严重程度统计NC | D9: NC总数 | F9: 轻 微 | H9: 一 般 | J9: 严 重
D10: =COUNTIF(B13:B14,"<>") -> 2 | F10: =COUNTIF(F13:F15,"=轻微") -> 0 | H10: =COUNTIF(F13:F15,"=一般") -> 2 | J10: =COUNTIF(F13:F15,"=严重") -> 0
B11: 不符合项问题（NC）列表
B12: 序 号 | C12: 问题描述 | F12: 严重程度 | G12: 责任人 | H12: 提交日期 | I12: 计划关闭日期 | J12: 纠正措施
B13: 1 | C13: 表2测量工作相关人员中，测试人员应为吴丹和李德馨 | F13: 一般 | G13: 王佳康 | H13: 2025.7.15 | I13: 2025.7.16 | J13: 修改表2，测试人员改为吴丹、李德馨
B14: 2 | C14: 表8中部分阶段的测量时机和开发计划中的进度安排不一 | F14: 一般 | G14: 王佳康 | H14: 2025.7.15 | I14: 2025.7.16 | J14: 对照软件开发计划的进度安排修改表8测量活动时间段
B15: 纠正措施验证情况：
B16: 纠正措施已实施，不符合项问题均按期关闭。 验证人/日期：

Sheet 006产品审核报告-质量保证计划2025.7.15
B1: 过程/产品审核报告
B2: 编号：ZDPX-2022020/0.0-QA-审核报告-006
B3: 项目名称 | C3: 测控体系辅助业务系统 | H3: 所处阶段 | I3: 软件需求分析
B4: 审核对象（过程名称/产品名称） | F4: 《软件质量保证计划》
B5: 审核人 | C5: 刘喻 | F5: 审核日期 | H5: 45853
B6: 审核依据 | C6: ZDPX-2022020/0.0-QA-检查单-006
B7: 审核内容概述：
B8: 审核内容概述： 本次审核的产品为质量保证计划，审核内容包括： 1）编写的规范性； 2）与其它相关文档的一致性； 3）内容的完整性和正确性； 4）上下文的一致性； 5）对模板的符合性。 经审核，发现2个不符合项。
B9: 按严重程度统计NC | D9: NC总数 | F9: 轻 微 | H9: 一 般 | J9: 严 重
D10: =COUNTIF(B13:B14,"<>") -> 2 | F10: =COUNTIF(F13:F15,"=轻微") -> 0 | H10: =COUNTIF(F13:F15,"=一般") -> 1 | J10: =COUNTIF(F13:F15,"=严重") -> 1
B11: 不符合项问题（NC）列表
B12: 序 号 | C12: 问题描述 | F12: 严重程度 | G12: 责任人 | H12: 提交日期 | I12: 计划关闭日期 | J12: 纠正措施
B13: 1 | C13: 表5阶段划分，缺少出厂检验和验收交付阶段 | F13: 严重 | G13: 高蕾 | H13: 2025.7.15 | I13: 2025.7.16 | J13: 表5中增加出厂检验阶段、验收交付阶段
B14: 2 | C14: 6.4节，产品审核对象中有配置项测试计划、合格性测试说明、合格性测试报告，与上下文不一致，另外缺少技术说明书、软件使用说明书等。 | F14: 一般 | G14: 高蕾 | H14: 2025.7.15 | I14: 2025.7.16 | J14: 修改6.4节，合格性测试说明、合格性测试报告改为配置项测试说明和配置项测试报告
B15: 纠正措施验证情况：
B16: 纠正措施已实施，不符合项问题均按期关闭。 验证人/日期：

Sheet 007产品审核报告-配置管理计划2025.7.15
B1: 过程/产品审核报告
B2: 编号：ZDPX-2022020/0.0-QA-审核报告-007
B3: 项目名称 | C3: 测控体系辅助业务系统 | H3: 所处阶段 | I3: 软件需求分析
B4: 审核对象（过程名称/产品名称） | F4: 《配置管理计划》
B5: 审核人 | C5: 高蕾 | F5: 审核日期 | H5: 45853
B6: 审核依据 | C6: ZDPX-2022020/0.0-QA-检查单-007
B7: 审核内容概述：
B8: 审核内容概述： 本次审核的产品为配置管理计划，审核内容包括： 1）编写的规范性； 2）与其它相关文档的一致性； 3）内容的完整性和正确性； 4）上下文的一致性； 5）对模板的符合性。 经审核，发现2个不符合项。
B9: 按严重程度统计NC | D9: NC总数 | F9: 轻 微 | H9: 一 般 | J9: 严 重
D10: =COUNTIF(B13:B14,"<>") -> 2 | F10: =COUNTIF(F13:F15,"=轻微") -> 0 | H10: =COUNTIF(F13:F15,"=一般") -> 2 | J10: =COUNTIF(F13:F15,"=严重") -> 0
B11: 不符合项问题（NC）列表
B12: 序 号 | C12: 问题描述 | F12: 严重程度 | G12: 责任人 | H12: 提交日期 | I12: 计划关闭日期 | J12: 纠正措施
B13: 1 | C13: 4.1节中，通过配置项测试后的源代码版本应是V0.1.0 | F13: 一般 | G13: 方小娟 | H13: 2025.7.15 | I13: 2025.7.16 | J13: 修改4.1节，通过配置项测试的源代码版本从V0.1.0开始
B14: 2 | C14: 表3配置项清单中遗漏了技术说明书和培训教材 | F14: 一般 | G14: 方小娟 | H14: 2025.7.15 | I14: 2025.7.16 | J14: 表3配置项清单中增加技术说明书和培训教材
B15: 纠正措施验证情况：
B16: 纠正措施已实施，不符合项问题均按期关闭。 验证人/日期：

Sheet 008产品审核报告-软件开发计划2025.7.15
B1: 过程/产品审核报告
B2: 编号：ZDPX-2022020/0.0-QA-审核报告-008
B3: 项目名称 | C3: 测控体系辅助业务系统 | H3: 所处阶段 | I3: 软件需求分析
B4: 审核对象（过程名称/产品名称） | F4: 《软件开发计划》
B5: 审核人 | C5: 高蕾 | F5: 审核日期 | H5: 45853
B6: 审核依据 | C6: ZDPX-2022020/0.0-QA-检查单-008
B7: 审核内容概述：
B8: 审核内容概述： 本次审核的产品为软件开发计划，审核内容包括： 1） 编写的规范性； 2） 与其它相关文档的一致性； 3） 对模板的符合性； 4） 上下文的一致性； 5） 内容的正确性。 经审核，发现2个不符合项。
B9: 按严重程度统计NC | D9: NC总数 | F9: 轻 微 | H9: 一 般 | J9: 严 重
D10: =COUNTIF(B13:B15,"<>") -> 2 | F10: =COUNTIF(F13:F16,"=轻微") -> 0 | H10: =COUNTIF(F13:F16,"=一般") -> 2 | J10: =COUNTIF(F13:F16,"=严重") -> 0
B11: 不符合项问题（NC）列表
B12: 序 号 | C12: 问题描述 | F12: 严重程度 | G12: 责任人 | H12: 提交日期 | I12: 计划关闭日期 | J12: 纠正措施
B13: 1 | C13: 表3-1项目文档要求与软件研制任务书不一致，缺少培训教材 | F13: 一般 | G13: 王佳康 | H13: 2025.7.15 | I13: 2025.7.16 | J13: 表3-1项目文档增加培训教材
B14: 2 | C14: 5.2.6出厂所检验的工作内容与本项目合同要求的不一致。 | F14: 一般 | G14: 王佳康 | H14: 2025.7.15 | I14: 2025.7.16 | J14: 对照合同要求修改5.2.6出厂所检验的工作内容
B16: 纠正措施验证情况：
B17: 纠正措施已实施，不符合项问题均按期关闭。 验证人/日期：

Sheet 009项目策划审核报告-2025.7.16
B1: 过程/产品审核报告
B2: 编号：ZDPX-2022020/0.0-QA-审核报告-009
B3: 项目名称 | C3: 测控体系辅助业务系统 | H3: 所处阶段 | I3: 软件需求分析
B4: 审核对象（过程名称/产品名称） | F4: 项目策划
B5: 审核人 | C5: 高蕾 | F5: 审核日期 | H5: 45854
B6: 审核依据 | C6: ZDPX-2022020/0.0-QA-检查单-009
B7: 审核内容概述：
B8: 本次审核内容包括： 1） 策划准备活动。 2） 策划参数估计过程。 3） 项目计划的制定。 4） 对计划的承诺。 经审核，各项活动的流程、参与人员等均符合体系文件要求，未发现不符合项。
B9: 按严重程度统计NC | D9: NC总数 | F9: 轻 微 | H9: 一 般 | J9: 严 重
D10: =COUNTIF(B13:B15,"<>") -> 0 | F10: =COUNTIF(F13:F17,"=轻微") -> 0 | H10: =COUNTIF(F13:F17,"=一般") -> 0 | J10: =COUNTIF(F13:F17,"=严重") -> 0
B11: 不符合项问题（NC）列表
B12: 序 号 | C12: 问题描述 | F12: 严重程度 | G12: 责任人 | H12: 提交日期 | I12: 计划关闭日期 | J12: 纠正措施
B16: 纠正措施验证情况：
B17: 验证人/日期：

Sheet 010项目监控审核报告-2025.7.23（双周1）
B1: 过程/产品审核报告
B2: 编号：ZDPX-2022020/0.0-QA-审核报告-010
B3: 项目名称 | C3: 测控体系辅助业务系统 | H3: 所处阶段 | I3: 软件需求分析
B4: 审核对象（过程名称/产品名称） | F4: 项目监控
B5: 审核人 | C5: 高蕾 | F5: 审核日期 | H5: 45861
B6: 审核依据 | C6: ZDPX-2022020/0.0-QA-检查单-010
B7: 审核内容概述：
B8: 本次审核内容包括： 1） 个人工作报告的填写； 2） 对工作量、进度、风险、任务等的跟踪； 3） 项目例会的组织； 4) 项目进展报告的编写 经审核，未发现不符合项。
B9: 按严重程度统计NC | D9: NC总数 | F9: 轻 微 | H9: 一 般 | J9: 严 重
D10: =COUNTIF(B13:B14,"<>") -> 0 | F10: =COUNTIF(F13:F16,"=轻微") -> 0 | H10: =COUNTIF(F13:F16,"=一般") -> 0 | J10: =COUNTIF(F13:F16,"=严重") -> 0
B11: 不符合项问题（NC）列表
B12: 序 号 | C12: 问题描述 | F12: 严重程度 | G12: 责任人 | H12: 提交日期 | I12: 计划关闭日期 | J12: 纠正措施
B15: 纠正措施验证情况：
B16: 验证人/日期：

Sheet 011测量与绩效管理审核报告-2025.7.23（双周1）
B1: 过程/产品审核报告
B2: 编号：ZDPX-2022020/0.0-QA-审核报告-011
B3: 项目名称 | C3: 测控体系辅助业务系统 | H3: 所处阶段 | I3: 软件需求分析
B4: 审核对象（过程名称/产品名称） | F4: 测量与绩效管理
B5: 审核人 | C5: 高蕾 | F5: 审核日期 | H5: 45861
B6: 审核依据 | C6: ZDPX-2022020/0.0-QA-检查单-011
B7: 审核内容概述：
B8: 本次审核内容包括： 1）测量与分析活动的策划； 2）测量与分析活动的实施； 3）测量分析报告的编写 经审核，各项活动的流程、参与人员等均符合体系文件要求，未发现不符合项
B9: 按严重程度统计NC | D9: NC总数 | F9: 轻 微 | H9: 一 般 | J9: 严 重
D10: =COUNTIF(B13:B15,"<>") -> 0 | F10: =COUNTIF(F13:F17,"=轻微") -> 0 | H10: =COUNTIF(F13:F17,"=一般") -> 0 | J10: =COUNTIF(F13:F17,"=严重") -> 0
B11: 不符合项问题（NC）列表
B12: 序 号 | C12: 问题描述 | F12: 严重程度 | G12: 责任人 | H12: 提交日期 | I12: 计划关闭日期 | J12: 纠正措施
B16: 纠正措施验证情况：
B17: 验证人/日期：

Sheet 012配置管理审核报告-2025.7.31 (月)
B1: 过程/产品审核报告
B2: 编号：ZDPX-2022020/0.0-QA-审核报告-012
B3: 项目名称 | C3: 测控体系辅助业务系统 | H3: 所处阶段 | I3: 软件需求分析
B4: 审核对象（过程名称/产品名称） | F4: 配置管理
B5: 审核人 | C5: 高蕾 | F5: 审核日期 | H5: 45869
B6: 审核依据 | C6: ZDPX-2022020/0.0-QA-检查单-012
B7: 审核内容概述：
B8: 审核内容概述： 本次审核内容包括： 1） 配置管理库的管理和维护。 2） 软件开发计划等工作产品的入库流程。 3） 配置状态纪实。 4） 配置审核。 经审核，发现2个不符合项。
B9: 按严重程度统计NC | D9: NC总数 | F9: 轻 微 | H9: 一 般 | J9: 严 重
D10: =COUNTIF(B13:B15,"<>") -> 2 | F10: =COUNTIF(F13:F17,"=轻微") -> 2 | H10: =COUNTIF(F13:F17,"=一般") -> 0 | J10: =COUNTIF(F13:F17,"=严重") -> 0
B11: 不符合项问题（NC）列表
B12: 序 号 | C12: 问题描述 | F12: 严重程度 | G12: 责任人 | H12: 提交日期 | I12: 计划关闭日期 | J12: 纠正措施
B13: 1 | C13: 入库单002中，质量保证计划的标识填写错误。 | F13: 轻微 | G13: 方小娟 | H13: 2025.7.31 | I13: 2025.8.1 | J13: 修改入库单中质量保证计划的标识
B14: 2 | C14: 配置管理清单002中，质量保证计划的标识错误。 | F14: 轻微 | G14: 方小娟 | H14: 2025.7.31 | I14: 2025.8.1 | J14: 修改配置管理清单002中错误的标识
B16: 纠正措施验证情况：
B17: 纠正措施已实施，不符合项问题均按期关闭。 验证人/日期：

Sheet 013项目监控审核报告-2025.8.6（双周2）
B1: 过程/产品审核报告
B2: 编号：ZDPX-2022020/0.0-QA-审核报告-013
B3: 项目名称 | C3: 测控体系辅助业务系统 | H3: 所处阶段 | I3: 软件需求分析
B4: 审核对象（过程名称/产品名称） | F4: 项目监控
B5: 审核人 | C5: 高蕾 | F5: 审核日期 | H5: 45875
B6: 审核依据 | C6: ZDPX-2022020/0.0-QA-检查单-013
B7: 审核内容概述：
B8: 本次审核内容包括： 1） 个人工作报告的填写； 2） 对工作量、进度、风险、任务等的跟踪； 3） 项目例会的组织； 4) 项目进展报告的编写 经审核，发现2个不符合项。
B9: 按严重程度统计NC | D9: NC总数 | F9: 轻 微 | H9: 一 般 | J9: 严 重
D10: =COUNTIF(B13:B14,"<>") -> 2 | F10: =COUNTIF(F13:F16,"=轻微") -> 0 | H10: =COUNTIF(F13:F16,"=一般") -> 2 | J10: =COUNTIF(F13:F16,"=严重") -> 0
B11: 不符合项问题（NC）列表
B12: 序 号 | C12: 问题描述 | F12: 严重程度 | G12: 责任人 | H12: 提交日期 | I12: 计划关闭日期 | J12: 纠正措施
B13: 1 | C13: 本节点未对利益相关方参与计划进行跟踪 | F13: 一般 | G13: 王佳康 | H13: 2025.8.6 | I13: 2025.8.7 | J13: 补利益相关方参与计划跟踪记录
B14: 2 | C14: 孙迎斌未提交周报 | F14: 一般 | G14: 孙迎斌 | H14: 2025.8.6 | I14: 2025.8.7 | J14: 孙迎斌补提交周报
B15: 纠正措施验证情况：
B16: 纠正措施已实施，不符合项问题均按期关闭。 验证人/日期：

Sheet 014测量与绩效管理审核报告-2025.8.6（双周2）
B1: 过程/产品审核报告
B2: 编号：ZDPX-2022020/0.0-QA-审核报告-014
B3: 项目名称 | C3: 测控体系辅助业务系统 | H3: 所处阶段 | I3: 软件需求分析
B4: 审核对象（过程名称/产品名称） | F4: 测量与绩效管理
B5: 审核人 | C5: 高蕾 | F5: 审核日期 | H5: 45875
B6: 审核依据 | C6: ZDPX-2022020/0.0-QA-检查单-014
B7: 审核内容概述：
B8: 本次审核内容包括： 1）测量与分析活动的策划； 2）测量与分析活动的实施； 3）测量分析报告的编写 经审核，各项活动的流程、参与人员等均符合体系文件要求，未发现不符合项
B9: 按严重程度统计NC | D9: NC总数 | F9: 轻 微 | H9: 一 般 | J9: 严 重
D10: =COUNTIF(B13:B15,"<>") -> 0 | F10: =COUNTIF(F13:F17,"=轻微") -> 0 | H10: =COUNTIF(F13:F17,"=一般") -> 0 | J10: =COUNTIF(F13:F17,"=严重") -> 0
B11: 不符合项问题（NC）列表
B12: 序 号 | C12: 问题描述 | F12: 严重程度 | G12: 责任人 | H12: 提交日期 | I12: 计划关闭日期 | J12: 纠正措施
B16: 纠正措施验证情况：
B17: 验证人/日期：

Sheet 015产品审核报告-软件需规2025.8.20
B1: 过程/产品审核报告
B2: 编号：ZDPX-2022020/0.0-QA-审核报告-015
B3: 项目名称 | C3: 测控体系辅助业务系统 | H3: 所处阶段 | I3: 软件需求分析
B4: 审核对象（过程名称/产品名称） | F4: 软件需求规格说明
B5: 审核人 | C5: 高蕾 | F5: 审核日期 | H5: 45889
B6: 审核依据 | C6: ZDPX-2022020/0.0-QA-检查单-015
B7: 审核内容概述：
B8: 本次审核的需求规格说明，审核内容包括： 1） 编写的规范性； 2） 与其它相关文档的一致性； 3） 对模板的符合性； 4） 上下文的一致性； 5） 内容的正确性。 经审核，发现4个不符合项。
B9: 按严重程度统计NC | D9: NC总数 | F9: 轻 微 | H9: 一 般 | J9: 严 重
D10: =COUNTIF(B13:B16,"<>") -> 4 | F10: =COUNTIF(F13:F18,"=轻微") -> 0 | H10: =COUNTIF(F13:F18,"=一般") -> 1 | J10: =COUNTIF(F13:F18,"=严重") -> 3
B11: 不符合项问题（NC）列表
B12: 序 号 | C12: 问题描述 | F12: 严重程度 | G12: 责任人 | H12: 提交日期 | I12: 计划关闭日期 | J12: 纠正措施
B13: 1 | C13: 3.3.1测控方案设计功能、3.3.2任务监视功能、3.3.3预警信息模拟功能、3.3.5效能评估功能需要细化，未能覆盖任务书中的要求。 | F13: 严重 | G13: 王佳康 | H13: 2025.8.20 | I13: 2025.8.22 | J13: 对照任务书对3.3.1测控方案设计功能、3.3.2任务监视功能、3.3.3预警信息模拟功能、3.3.5效能评估功能进行细化
B14: 2 | C14: 建议增加各功能点涉及到的算法、模型及指标体系内容。 | F14: 一般 | G14: 王佳康 | H14: 2025.8.20 | I14: 2025.8.22 | J14: 增加第10章主要算法、模型、指标体系说明
B15: 3 | C15: 缺少任务中的环境需求 | F15: 严重 | G15: 王佳康 | H15: 2025.8.20 | I15: 2025.8.22 | J15: 第7章非功能性需求增加7.2设计和实现约束、7.3环境需求。
B16: 4 | C16: 缺少任务书中设计和实现约束相关内容 | F16: 严重 | G16: 王佳康 | H16: 2025.8.20 | I16: 2025.8.22 | J16: 第7章非功能性需求增加7.2设计和实现约束、7.3环境需求。
B17: 纠正措施验证情况：
B18: 纠正措施已实施，不符合项问题均按期关闭。 验证人/日期：

Sheet 016产品审核报告-软件测试计划2025.8.21
B1: 过程/产品审核报告
B2: 编号：ZDPX-2022020/0.0-QA-审核报告-016
B3: 项目名称 | C3: 测控体系辅助业务系统 | H3: 所处阶段 | I3: 软件需求分析
B4: 审核对象（过程名称/产品名称） | F4: 配置项测试计划
B5: 审核人 | C5: 高蕾 | F5: 审核日期 | H5: 45890
B6: 审核依据 | C6: ZDPX-2022020/0.0-QA-检查单-016
B7: 审核内容概述：
B8: 本次审核软件测试计划，审核内容包括： 1） 编写的规范性； 2） 与其它相关文档的一致性； 3） 对模板的符合性； 4） 上下文的一致性； 5） 内容的正确性。 经审核，未发现不符合项。
B9: 按严重程度统计NC | D9: NC总数 | F9: 轻 微 | H9: 一 般 | J9: 严 重
D10: =COUNTIF(B13:B15,"<>") -> 0 | F10: =COUNTIF(F13:F18,"=轻微") -> 0 | H10: =COUNTIF(F13:F18,"=一般") -> 0 | J10: =COUNTIF(F13:F18,"=严重") -> 0
B11: 不符合项问题（NC）列表
B12: 序 号 | C12: 问题描述 | F12: 严重程度 | G12: 责任人 | H12: 提交日期 | I12: 计划关闭日期 | J12: 纠正措施
B17: 纠正措施验证情况：
B18: 验证人/日期：

Sheet 017验证与确认审核报告-2025.8.22
B1: 过程/产品审核报告
B2: 编号：ZDPX-2022020/0.0-QA-审核报告-017
B3: 项目名称 | C3: 测控体系辅助业务系统 | H3: 所处阶段 | I3: 软件需求分析
B4: 审核对象（过程名称/产品名称） | F4: 验证与确认
B5: 审核人 | C5: 高蕾 | F5: 审核日期 | H5: 45891
B6: 审核依据 | C6: ZDPX-2022020/0.0-QA-检查单-017
B7: 审核内容概述：
B8: 本次审核内容包括： 1） 评审会的组织过程。 2） 评审会的参与人员符合性。 3） 对评审缺陷的处理。 经审核，未发现不符合项。
B9: 按严重程度统计NC | D9: NC总数 | F9: 轻 微 | H9: 一 般 | J9: 严 重
D10: =COUNTIF(B13:B16,"<>") -> 0 | F10: =COUNTIF(F13:F16,"=轻微") -> 0 | H10: =COUNTIF(F13:F16,"=一般") -> 0 | J10: =COUNTIF(F13:F16,"=严重") -> 0
B11: 不符合项问题（NC）列表
B12: 序 号 | C12: 问题描述 | F12: 严重程度 | G12: 责任人 | H12: 提交日期 | I12: 计划关闭日期 | J12: 纠正措施
B17: 纠正措施验证情况：
B18: 验证人/日期：
I41: 42956

Sheet 018项目监控审核报告-2025.8.25（阶段）
B1: 过程/产品审核报告
B2: 编号：ZDPX-2022020/0.0-QA-审核报告-018
B3: 项目名称 | C3: 测控体系辅助业务系统 | H3: 所处阶段 | I3: 软件需求分析
B4: 审核对象（过程名称/产品名称） | F4: 项目监控
B5: 审核人 | C5: 高蕾 | F5: 审核日期 | H5: 45894
B6: 审核依据 | C6: ZDPX-2022020/0.0-QA-检查单-018
B7: 审核内容概述：
B8: 本次审核内容包括： 1） 个人工作报告的填写； 2） 对工作量、进度、风险、任务等的跟踪； 3） 项目例会的组织； 4) 项目进展报告的编写 经审核，发现2个不符合项。
B9: 按严重程度统计NC | D9: NC总数 | F9: 轻 微 | H9: 一 般 | J9: 严 重
D10: =COUNTIF(B13:B15,"<>") -> 2 | F10: =COUNTIF(F13:F17,"=轻微") -> 0 | H10: =COUNTIF(F13:F17,"=一般") -> 2 | J10: =COUNTIF(F13:F17,"=严重") -> 0
B11: 不符合项问题（NC）列表
B12: 序 号 | C12: 问题描述 | F12: 严重程度 | G12: 责任人 | H12: 提交日期 | I12: 计划关闭日期 | J12: 纠正措施
B13: 1 | C13: 未见本阶段的需求管理情况工作报告 | F13: 一般 | G13: 王佳康 | H13: 2025.8.25 | I13: 2025.8.27 | J13: 补本阶段的需求管理情况工作报告
B14: 2 | C14: 项目进展报告缺少项目总监签字 | F14: 一般 | G14: 王佳康 | H14: 2025.8.25 | I14: 2025.8.27 | J14: 本阶段项目进展报告补项目总监的签字
B16: 纠正措施验证情况：
B17: 纠正措施已实施，不符合项问题均按期关闭。 验证人/日期：

Sheet 019测量与绩效管理审核报告-2025.8.25（阶段）
B1: 过程/产品审核报告
B2: 编号：ZDPX-2022020/0.0-QA-审核报告-019
B3: 项目名称 | C3: 测控体系辅助业务系统 | H3: 所处阶段 | I3: 软件需求分析
B4: 审核对象（过程名称/产品名称） | F4: 测量与绩效管理
B5: 审核人 | C5: 高蕾 | F5: 审核日期 | H5: 45894
B6: 审核依据 | C6: ZDPX-2022020/0.0-QA-检查单-019
B7: 审核内容概述：
B8: 本次审核内容包括： 1）测量与分析活动的实施； 2）测量分析报告的编写 经审核，发现1个不符合项。
B9: 按严重程度统计NC | D9: NC总数 | F9: 轻 微 | H9: 一 般 | J9: 严 重
D10: =COUNTIF(B13:B14,"<>") -> 1 | F10: =COUNTIF(F13:F16,"=轻微") -> 0 | H10: =COUNTIF(F13:F16,"=一般") -> 1 | J10: =COUNTIF(F13:F16,"=严重") -> 0
B11: 不符合项问题（NC）列表
B12: 序 号 | C12: 问题描述 | F12: 严重程度 | G12: 责任人 | H12: 提交日期 | I12: 计划关闭日期 | J12: 纠正措施
B13: 1 | C13: 未见对配置项测试计划规模的采集数据 | F13: 一般 | G13: 王佳康 | H13: 2025.8.25 | I13: 2025.8.27 | J13: 补交配置项测试计划规模采集数据
B15: 纠正措施验证情况：
B16: 纠正措施已实施，不符合项问题均按期关闭。 验证人/日期：

Sheet 020需求开发与管理审核报告-2025.8.25
B1: 过程/产品审核报告
B2: 编号：ZDPX-2022020/0.0-QA-审核报告-020
B3: 项目名称 | C3: 测控体系辅助业务系统 | H3: 所处阶段 | I3: 软件需求分析
B4: 审核对象（过程名称/产品名称） | F4: 需求开发与管理
B5: 审核人 | C5: 高蕾 | F5: 审核日期 | H5: 45894
B6: 审核依据 | C6: ZDPX-2022020/0.0-QA-检查单-020
B7: 审核内容概述：
B8: 本次审核内容包括： 1）软件需求的开发与确认； 2）需求管理活动的策划； 3）分配基线的建立； 4）软件开发计划与软件研制任务书的追踪关系 5）需求规格说明与研制任务书的追踪关系 6）配置项测试计划与软件需求规格说明的追踪关系。 7）需求管理工作报告 经审核，发现1个不符合项。
B9: 按严重程度统计NC | D9: NC总数 | F9: 轻 微 | H9: 一 般 | J9: 严 重
D10: =COUNTIF(B13:B15,"<>") -> 1 | F10: =COUNTIF(F13:F15,"=轻微") -> 0 | H10: =COUNTIF(F13:F15,"=一般") -> 1 | J10: =COUNTIF(F13:F15,"=严重") -> 0
B11: 不符合项问题（NC）列表
B12: 序 号 | C12: 问题描述 | F12: 严重程度 | G12: 责任人 | H12: 提交日期 | I12: 计划关闭日期 | J12: 纠正措施
A13: 1 | B13: 1 | C13: 未见本阶段的需求管理情况工作报告 | F13: 一般 | G13: 王佳康 | H13: 2025.8.25 | I13: 2025.8.27 | J13: 补本阶段的需求管理情况工作报告
B16: 纠正措施验证情况：
B17: 纠正措施已实施，不符合项问题均按期关闭。 验证人/日期：
I39: 42956

Sheet 021配置管理审核报告-2025.8.25
B1: 过程/产品审核报告
B2: 编号：ZDPX-2022020/0.0-QA-审核报告-021
B3: 项目名称 | C3: 测控体系辅助业务系统 | H3: 所处阶段 | I3: 软件需求分析
B4: 审核对象（过程名称/产品名称） | F4: 配置管理
B5: 审核人 | C5: 高蕾 | F5: 审核日期 | H5: 45894
B6: 审核依据 | C6: ZDPX-2022020/0.0-QA-检查单-021
B7: 审核内容概述：
B8: 审核内容概述： 本次审核内容包括： 1） 配置管理库的管理和维护。 2） 软件需规的入库流程。 3） 分配基线的建立、审批和发布。 4） 配置状态纪实。 5） 配置审核。 经审核，发现2个不符合项。
B9: 按严重程度统计NC | D9: NC总数 | F9: 轻 微 | H9: 一 般 | J9: 严 重
D10: =COUNTIF(B13:B15,"<>") -> 3 | F10: =COUNTIF(F13:F17,"=轻微") -> 1 | H10: =COUNTIF(F13:F17,"=一般") -> 2 | J10: =COUNTIF(F13:F17,"=严重") -> 0
B11: 不符合项问题（NC）列表
B12: 序 号 | C12: 问题描述 | F12: 严重程度 | G12: 责任人 | H12: 提交日期 | I12: 计划关闭日期 | J12: 纠正措施
B13: 1 | C13: 受控库中配置项测试计划缺少标识 | F13: 轻微 | G13: 方小娟 | H13: 2025.8.25 | I13: 2025.8.27 | J13: 检查受控库中所有配置项的标识，补充缺失的标识
B14: 2 | C14: 基线发布单缺少项目总监签字 | F14: 一般 | G14: 方小娟 | H14: 2025.8.25 | I14: 2025.8.27 | J14: 基线发布单提交给项目总监签字
B15: 3 | C15: 分配基线审核报告缺少功能审核的内容 | F15: 一般 | G15: 方小娟 | H15: 2025.8.25 | I15: 2025.8.27 | J15: 重新进行分配基线审核并完成审核报告
B16: 纠正措施验证情况：
B17: 纠正措施已实施，不符合项问题均按期关闭。 验证人/日期：
